Workbook

Sheet README
A1: Phase 5 hand check: the backtest engine recomputed with plain spreadsheet formulas.
A2: Built by `python -m src.engine.handcheck`; test/test_engine_checks.py compares the stored formula values with a fresh engine run.
A4: Inputs: simulated daily excess returns of two instruments, A and B, and a daily risk-free rate (sheet Daily, columns A-E).
A5: Two recipes: positions per unit of size are held in every month of their year (sheet Inputs).
A6: Rule: size for month m+1 = min(cap, c_t / RV_t), with RV_t and c_t from the mix held in m+1, at the end of month t = m.
A7: c_t = STDEV(next-month returns) / STDEV(next-month return x signal), over the pairs complete by the end of t (expanding range).
A8: Execution: trade at the month's last close; positions drift within the month; turnover = |new - drifted|, cost = kappa x turnover.
A9: Cash below zero grows at rf + borrow spread; a short grows at its return + short fee (both accrued daily, 252 a year).
A10: Net return = (1 - trading cost) x account growth - 1. Excess = net - Rf of the month.
A11: Buy-and-hold: the same recipe at size 1, traded on the same dates at the same costs.
A13: Sheet Check: the column 'difference' should be zero to about 1e-15 (floating point).

Sheet Check
A1: holding month | B1: quantity | C1: spreadsheet | D1: engine | E1: difference
A2: 2016-08 | B2: forecast | C2: =Monthly!R8 -> 0.0011360445 | D2: 0.0011360445 | E2: =C2-D2 -> -2.8666305e-16
A3: 2016-08 | B3: c | C3: =Monthly!T8 -> 0.0021716393 | D3: 0.0021716393 | E3: =C3-D3 -> -1.201296e-16
A4: 2016-08 | B4: size | C4: =Monthly!V8 -> 1.3 | D4: 1.3 | E4: =C4-D4 -> 0
A5: 2016-08 | B5: w_A | C5: =Monthly!X9 -> 1.04 | D5: 1.04 | E5: =C5-D5 -> 0
A6: 2016-08 | B6: w_B | C6: =Monthly!Y9 -> 0.78 | D6: 0.78 | E6: =C6-D6 -> 0
A7: 2016-08 | B7: drift_A | C7: =Monthly!AE9 -> 1.0739465 | D7: 1.0739465 | E7: =C7-D7 -> -1.110223e-15
A8: 2016-08 | B8: drift_B | C8: =Monthly!AF9 -> 0.80734118 | D8: 0.80734118 | E8: =C8-D8 -> 1.4432899e-15
A9: 2016-08 | B9: turnover | C9: =Monthly!AI9 -> 1.82 | D9: 1.82 | E9: =C9-D9 -> 0
A10: 2016-08 | B10: trading | C10: =Monthly!AJ9 -> 0.0013 | D10: 0.0013 | E10: =C10-D10 -> 2.1684043e-19
A11: 2016-08 | B11: net | C11: =Monthly!AK9 -> -0.069852889 | D11: -0.069852889 | E11: =C11-D11 -> 2.484124e-15
A12: 2016-08 | B12: excess | C12: =Monthly!AL9 -> -0.070364817 | D12: -0.070364817 | E12: =C12-D12 -> 1.9984014e-15
A13: 2016-08 | B13: bench_turnover | C13: =Monthly!AX9 -> 1.4 | D13: 1.4 | E13: =C13-D13 -> 0
A14: 2016-08 | B14: bench_net | C14: =Monthly!AZ9 -> -0.053525533 | D14: -0.053525533 | E14: =C14-D14 -> 2.0053403e-15
A15: 2016-08 | B15: bench_excess | C15: =Monthly!BA9 -> -0.05403746 | D15: -0.05403746 | E15: =C15-D15 -> 1.5196178e-15
A16: 2016-10 | B16: forecast | C16: =Monthly!R10 -> 0.0025713485 | D16: 0.0025713485 | E16: =C16-D16 -> -1.4441573e-16
A17: 2016-10 | B17: c | C17: =Monthly!T10 -> 0.0017081034 | D17: 0.0017081034 | E17: =C17-D17 -> -3.0422713e-16
A18: 2016-10 | B18: size | C18: =Monthly!V10 -> 0.66428309 | D18: 0.66428309 | E18: =C18-D18 -> -2.553513e-15
A19: 2016-10 | B19: w_A | C19: =Monthly!X11 -> 0.53142647 | D19: 0.53142647 | E19: =C19-D19 -> -2.220446e-15
A20: 2016-10 | B20: w_B | C20: =Monthly!Y11 -> 0.39856986 | D20: 0.39856986 | E20: =C20-D20 -> -1.9984014e-15
A21: 2016-10 | B21: drift_A | C21: =Monthly!AE11 -> 0.50676212 | D21: 0.50676212 | E21: =C21-D21 -> -3.663736e-15
A22: 2016-10 | B22: drift_B | C22: =Monthly!AF11 -> 0.41936222 | D22: 0.41936222 | E22: =C22-D22 -> -9.4368957e-16
A23: 2016-10 | B23: turnover | C23: =Monthly!AI11 -> 0.28947042 | D23: 0.28947042 | E23: =C23-D23 -> 1.7708057e-14
A24: 2016-10 | B24: trading | C24: =Monthly!AJ11 -> 0.0001999778 | D24: 0.0001999778 | E24: =C24-D24 -> 1.4989095e-17
A25: 2016-10 | B25: net | C25: =Monthly!AK11 -> -0.052091231 | D25: -0.052091231 | E25: =C25-D25 -> -1.7971735e-15
A26: 2016-10 | B26: excess | C26: =Monthly!AL11 -> -0.052630048 | D26: -0.052630048 | E26: =C26-D26 -> -5.1347815e-16
A27: 2016-10 | B27: bench_turnover | C27: =Monthly!AX11 -> 0.030499358 | D27: 0.030499358 | E27: =C27-D27 -> 2.0504431e-15
A28: 2016-10 | B28: bench_net | C28: =Monthly!AZ11 -> -0.078592899 | D28: -0.078592899 | E28: =C28-D28 -> -2.5257574e-15
A29: 2016-10 | B29: bench_excess | C29: =Monthly!BA11 -> -0.079131716 | D29: -0.079131716 | E29: =C29-D29 -> -1.2490009e-15
A30: 2016-12 | B30: forecast | C30: =Monthly!R12 -> 0.00077335323 | D30: 0.00077335323 | E30: =C30-D30 -> 7.8604658e-17
A31: 2016-12 | B31: c | C31: =Monthly!T12 -> 0.0019255356 | D31: 0.0019255356 | E31: =C31-D31 -> -1.8496489e-16
A32: 2016-12 | B32: size | C32: =Monthly!V12 -> 1.3 | D32: 1.3 | E32: =C32-D32 -> 0
A33: 2016-12 | B33: w_A | C33: =Monthly!X13 -> 1.04 | D33: 1.04 | E33: =C33-D33 -> 0
A34: 2016-12 | B34: w_B | C34: =Monthly!Y13 -> 0.78 | D34: 0.78 | E34: =C34-D34 -> 0
A35: 2016-12 | B35: drift_A | C35: =Monthly!AE13 -> 0.99753389 | D35: 0.99753389 | E35: =C35-D35 -> 5.5511151e-16
A36: 2016-12 | B36: drift_B | C36: =Monthly!AF13 -> 0.75708232 | D36: 0.75708232 | E36: =C36-D36 -> 1.2212453e-15
A37: 2016-12 | B37: turnover | C37: =Monthly!AI13 -> 0.038893549 | D37: 0.038893549 | E37: =C37-D37 -> 1.7832957e-15
A38: 2016-12 | B38: trading | C38: =Monthly!AJ13 -> 3.4875694e-05 | D38: 3.4875694e-05 | E38: =C38-D38 -> 2.3821277e-16
A39: 2016-12 | B39: net | C39: =Monthly!AK13 -> 0.087721582 | D39: 0.087721582 | E39: =C39-D39 -> -1.56819e-15
A40: 2016-12 | B40: excess | C40: =Monthly!AL13 -> 0.087113006 | D40: 0.087113006 | E40: =C40-D40 -> -5.8286709e-16
...

Sheet Monthly
A1: month | B1: recipe held | C1: year | D1: Rf (month) | E1: ret1: excess return, mix 1 | F1: RV1 | G1: signal1 = 1/RV1 | H1: y1 = next ret1 | I1: z1 = y1 x signal1 | J1: c1 (pairs up to the row before) | K1: ret2 | L1: RV2 | M1: signal2 | N1: y2 | O1: z2 | P1: c2 | Q1: recipe next month | R1: forecast (RV of the next recipe's mix) | S1: signal | T1: c | U1: c x signal | V1: size for next month (capped) | W1: size held | X1: w_A | Y1: w_B | Z1: cash | AA1: growth A | AB1: growth B | AC1: growth cash | AD1: account growth | AE1: drift_A | AF1: drift_B | AG1: |trade A| | AH1: |trade B| | AI1: turnover | AJ1: trading cost | AK1: net | AL1: excess | AM1: bench w_A | AN1: bench w_B | AO1: bench cash | AP1: bench growth A | AQ1: bench growth B | AR1: bench growth cash | AS1: bench account growth | AT1: bench drift_A | AU1: bench drift_B | AV1: bench |trade A| | AW1: bench |trade B| | AX1: bench turnover | AY1: bench trading cost | AZ1: bench net | BA1: bench excess
A2: 2016-01 | B2: =MATCH(C2,Inputs!$D$2:$D$3,0) -> 1 | C2: =VALUE(LEFT(A2,4)) -> 2016 | D2: =EXP(SUMIFS(Daily!$L$2:$L$504,Daily!$B$2:$B$504,A2))-1 -> 0.00020202875 | E2: =EXP(SUMIFS(Daily!$J$2:$J$504,Daily!$B$2:$B$504,A2))-EXP(SUMIFS(Daily!$L$2:$L$504,Daily!$B$2:$B$504,A2)) -> -0.020173769 | F2: =SUMIFS(Daily!$H$2:$H$504,Daily!$B$2:$B$504,A2) -> 0.0044281118 | G2: =1/F2 -> 225.82989 | H2: =E3 -> 0.076451976 | I2: =H2*G2 -> 17.265141 | K2: =EXP(SUMIFS(Daily!$K$2:$K$504,Daily!$B$2:$B$504,A2))-EXP(SUMIFS(Daily!$L$2:$L$504,Daily!$B$2:$B$504,A2)) -> 0.081841663 | L2: =SUMIFS(Daily!$I$2:$I$504,Daily!$B$2:$B$504,A2) -> 0.0016086537 | M2: =1/L2 -> 621.63784 | N2: =K3 -> 0.014763918 | O2: =N2*M2 -> 9.1778103
A3: 2016-02 | B3: =MATCH(C3,Inputs!$D$2:$D$3,0) -> 1 | C3: =VALUE(LEFT(A3,4)) -> 2016 | D3: =EXP(SUMIFS(Daily!$L$2:$L$504,Daily!$B$2:$B$504,A3))-1 -> 0.00024349872 | E3: =EXP(SUMIFS(Daily!$J$2:$J$504,Daily!$B$2:$B$504,A3))-EXP(SUMIFS(Daily!$L$2:$L$504,Daily!$B$2:$B$504,A3)) -> 0.076451976 | F3: =SUMIFS(Daily!$H$2:$H$504,Daily!$B$2:$B$504,A3) -> 0.0056592952 | G3: =1/F3 -> 176.70045 | H3: =E4 -> -0.0001680303 | I3: =H3*G3 -> -0.02969103 | K3: =EXP(SUMIFS(Daily!$K$2:$K$504,Daily!$B$2:$B$504,A3))-EXP(SUMIFS(Daily!$L$2:$L$504,Daily!$B$2:$B$504,A3)) -> 0.014763918 | L3: =SUMIFS(Daily!$I$2:$I$504,Daily!$B$2:$B$504,A3) -> 0.0032904024 | M3: =1/L3 -> 303.9142 | N3: =K4 -> 0.037870645 | O3: =N3*M3 -> 11.509427
A4: 2016-03 | B4: =MATCH(C4,Inputs!$D$2:$D$3,0) -> 1 | C4: =VALUE(LEFT(A4,4)) -> 2016 | D4: =EXP(SUMIFS(Daily!$L$2:$L$504,Daily!$B$2:$B$504,A4))-1 -> 0.00030438241 | E4: =EXP(SUMIFS(Daily!$J$2:$J$504,Daily!$B$2:$B$504,A4))-EXP(SUMIFS(Daily!$L$2:$L$504,Daily!$B$2:$B$504,A4)) -> -0.0001680303 | F4: =SUMIFS(Daily!$H$2:$H$504,Daily!$B$2:$B$504,A4) -> 0.0019916547 | G4: =1/F4 -> 502.09506 | H4: =E5 -> 0.072560158 | I4: =H4*G4 -> 36.432097 | K4: =EXP(SUMIFS(Daily!$K$2:$K$504,Daily!$B$2:$B$504,A4))-EXP(SUMIFS(Daily!$L$2:$L$504,Daily!$B$2:$B$504,A4)) -> 0.037870645 | L4: =SUMIFS(Daily!$I$2:$I$504,Daily!$B$2:$B$504,A4) -> 0.0022757149 | M4: =1/L4 -> 439.42235 | N4: =K5 -> 0.025952822 | O4: =N4*M4 -> 11.40425
A5: 2016-04 | B5: =MATCH(C5,Inputs!$D$2:$D$3,0) -> 1 | C5: =VALUE(LEFT(A5,4)) -> 2016 | D5: =EXP(SUMIFS(Daily!$L$2:$L$504,Daily!$B$2:$B$504,A5))-1 -> 0.00032624589 | E5: =EXP(SUMIFS(Daily!$J$2:$J$504,Daily!$B$2:$B$504,A5))-EXP(SUMIFS(Daily!$L$2:$L$504,Daily!$B$2:$B$504,A5)) -> 0.072560158 | F5: =SUMIFS(Daily!$H$2:$H$504,Daily!$B$2:$B$504,A5) -> 0.0028199131 | G5: =1/F5 -> 354.62085 | H5: =E6 -> 0.052119593 | I5: =H5*G5 -> 18.482695 | K5: =EXP(SUMIFS(Daily!$K$2:$K$504,Daily!$B$2:$B$504,A5))-EXP(SUMIFS(Daily!$L$2:$L$504,Daily!$B$2:$B$504,A5)) -> 0.025952822 | L5: =SUMIFS(Daily!$I$2:$I$504,Daily!$B$2:$B$504,A5) -> 0.0021720079 | M5: =1/L5 -> 460.40348 | N5: =K6 -> 0.030510273 | O5: =N5*M5 -> 14.047036
A6: 2016-05 | B6: =MATCH(C6,Inputs!$D$2:$D$3,0) -> 1 | C6: =VALUE(LEFT(A6,4)) -> 2016 | D6: =EXP(SUMIFS(Daily!$L$2:$L$504,Daily!$B$2:$B$504,A6))-1 -> 0.00036111786 | E6: =EXP(SUMIFS(Daily!$J$2:$J$504,Daily!$B$2:$B$504,A6))-EXP(SUMIFS(Daily!$L$2:$L$504,Daily!$B$2:$B$504,A6)) -> 0.052119593 | F6: =SUMIFS(Daily!$H$2:$H$504,Daily!$B$2:$B$504,A6) -> 0.0034393887 | G6: =1/F6 -> 290.74934 | H6: =E7 -> -0.021391246 | I6: =H6*G6 -> -6.2194905 | K6: =EXP(SUMIFS(Daily!$K$2:$K$504,Daily!$B$2:$B$504,A6))-EXP(SUMIFS(Daily!$L$2:$L$504,Daily!$B$2:$B$504,A6)) -> 0.030510273 | L6: =SUMIFS(Daily!$I$2:$I$504,Daily!$B$2:$B$504,A6) -> 0.003338302 | M6: =1/L6 -> 299.55349 | N6: =K7 -> -0.011153226 | O6: =N6*M6 -> -3.3409877
A7: 2016-06 | B7: =MATCH(C7,Inputs!$D$2:$D$3,0) -> 1 | C7: =VALUE(LEFT(A7,4)) -> 2016 | D7: =EXP(SUMIFS(Daily!$L$2:$L$504,Daily!$B$2:$B$504,A7))-1 -> 0.00041572149 | E7: =EXP(SUMIFS(Daily!$J$2:$J$504,Daily!$B$2:$B$504,A7))-EXP(SUMIFS(Daily!$L$2:$L$504,Daily!$B$2:$B$504,A7)) -> -0.021391246 | F7: =SUMIFS(Daily!$H$2:$H$504,Daily!$B$2:$B$504,A7) -> 0.0011919875 | G7: =1/F7 -> 838.93501 | H7: =E8 -> 0.046160082 | I7: =H7*G7 -> 38.725308 | K7: =EXP(SUMIFS(Daily!$K$2:$K$504,Daily!$B$2:$B$504,A7))-EXP(SUMIFS(Daily!$L$2:$L$504,Daily!$B$2:$B$504,A7)) -> -0.011153226 | L7: =SUMIFS(Daily!$I$2:$I$504,Daily!$B$2:$B$504,A7) -> 0.0023736483 | M7: =1/L7 -> 421.2924 | N7: =K8 -> -0.035492571 | O7: =N7*M7 -> -14.95275
A8: 2016-07 | B8: =MATCH(C8,Inputs!$D$2:$D$3,0) -> 1 | C8: =VALUE(LEFT(A8,4)) -> 2016 | D8: =EXP(SUMIFS(Daily!$L$2:$L$504,Daily!$B$2:$B$504,A8))-1 -> 0.00041113446 | E8: =EXP(SUMIFS(Daily!$J$2:$J$504,Daily!$B$2:$B$504,A8))-EXP(SUMIFS(Daily!$L$2:$L$504,Daily!$B$2:$B$504,A8)) -> 0.046160082 | F8: =SUMIFS(Daily!$H$2:$H$504,Daily!$B$2:$B$504,A8) -> 0.0011360445 | G8: =1/F8 -> 880.2472 | H8: =E9 -> -0.052514005 | I8: =H8*G8 -> -46.225306 | J8: =STDEV(H$2:H7)/STDEV(I$2:I7) -> 0.0021716393 | K8: =EXP(SUMIFS(Daily!$K$2:$K$504,Daily!$B$2:$B$504,A8))-EXP(SUMIFS(Daily!$L$2:$L$504,Daily!$B$2:$B$504,A8)) -> -0.035492571 | L8: =SUMIFS(Daily!$I$2:$I$504,Daily!$B$2:$B$504,A8) -> 0.0025668767 | M8: =1/L8 -> 389.57851 | N8: =K9 -> -0.032426384 | O8: =N8*M8 -> -12.632622 | P8: =STDEV(N$2:N7)/STDEV(O$2:O7) -> 0.00247856 | Q8: =B9 -> 1 | R8: =IF(Q8=1,F8,L8) -> 0.0011360445 | S8: =IF(Q8=1,G8,M8) -> 880.2472 | T8: =IF(Q8=1,J8,P8) -> 0.0021716393 | U8: =T8*S8 -> 1.9115794 | V8: =MIN(Inputs!$B$2,MAX(0,U8)) -> 1.3
A9: 2016-08 | B9: =MATCH(C9,Inputs!$D$2:$D$3,0) -> 1 | C9: =VALUE(LEFT(A9,4)) -> 2016 | D9: =EXP(SUMIFS(Daily!$L$2:$L$504,Daily!$B$2:$B$504,A9))-1 -> 0.00051192729 | E9: =EXP(SUMIFS(Daily!$J$2:$J$504,Daily!$B$2:$B$504,A9))-EXP(SUMIFS(Daily!$L$2:$L$504,Daily!$B$2:$B$504,A9)) -> -0.052514005 | F9: =SUMIFS(Daily!$H$2:$H$504,Daily!$B$2:$B$504,A9) -> 0.0019478932 | G9: =1/F9 -> 513.37517 | H9: =E10 -> 0.010664273 | I9: =H9*G9 -> 5.474773 | J9: =STDEV(H$2:H8)/STDEV(I$2:I8) -> 0.0016994246 | K9: =EXP(SUMIFS(Daily!$K$2:$K$504,Daily!$B$2:$B$504,A9))-EXP(SUMIFS(Daily!$L$2:$L$504,Daily!$B$2:$B$504,A9)) -> -0.032426384 | L9: =SUMIFS(Daily!$I$2:$I$504,Daily!$B$2:$B$504,A9) -> 0.0022074053 | M9: =1/L9 -> 453.02057 | N9: =K10 -> -0.030535872 | O9: =N9*M9 -> -13.833378 | P9: =STDEV(N$2:N8)/STDEV(O$2:O8) -> 0.0024789169 | Q9: =B10 -> 1 | R9: =IF(Q9=1,F9,L9) -> 0.0019478932 | S9: =IF(Q9=1,G9,M9) -> 513.37517 | T9: =IF(Q9=1,J9,P9) -> 0.0016994246 | U9: =T9*S9 -> 0.87244238 | V9: =MIN(Inputs!$B$2,MAX(0,U9)) -> 0.87244238 | W9: =V8 -> 1.3 | X9: =W9*INDEX(Inputs!$E$2:$E$3,B9) -> 1.04 | Y9: =W9*INDEX(Inputs!$F$2:$F$3,B9) -> 0.78 | Z9: =1-X9-Y9 -> -0.82 | AA9: =IF(X9<0,EXP(SUMIFS(Daily!$O$2:$O$504,Daily!$B$2:$B$504,A9)),EXP(SUMIFS(Daily!$M$2:$M$504,Daily!$B$2:$B$504,A9))) -> 0.96175823 | AB9: =IF(Y9<0,EXP(SUMIFS(Daily!$P$2:$P$504,Daily!$B$2:$B$504,A9)),EXP(SUMIFS(Daily!$N$2:$N$504,Daily!$B$2:$B$504,A9))) -> 0.96400457 | AC9: =IF(Z9<0,EXP(SUMIFS(Daily!$Q$2:$Q$504,Daily!$B$2:$B$504,A9)),1+D9) -> 1.0009686 | AD9: =X9*AA9+Y9*AB9+Z9*AC9 -> 0.93135788 | AE9: =X9*AA9/AD9 -> 1.0739465 | AF9: =Y9*AB9/AD9 -> 0.80734118 | AG9: =ABS(X9-0) -> 1.04 | AH9: =ABS(Y9-0) -> 0.78 | AI9: =AG9+AH9 -> 1.82 | AJ9: =Inputs!$B$4*AG9+Inputs!$B$5*AH9 -> 0.0013 | AK9: =(1-AJ9)*AD9-1 -> -0.069852889 | AL9: =AK9-D9 -> -0.070364817 | AM9: =1*INDEX(Inputs!$E$2:$E$3,B9) -> 0.8 | AN9: =1*INDEX(Inputs!$F$2:$F$3,B9) -> 0.6 | AO9: =1-AM9-AN9 -> -0.4 | AP9: =IF(AM9<0,EXP(SUMIFS(Daily!$O$2:$O$504,Daily!$B$2:$B$504,A9)),EXP(SUMIFS(Daily!$M$2:$M$504,Daily!$B$2:$B$504,A9))) -> 0.96175823 | AQ9: =IF(AN9<0,EXP(SUMIFS(Daily!$P$2:$P$504,Daily!$B$2:$B$504,A9)),EXP(SUMIFS(Daily!$N$2:$N$504,Daily!$B$2:$B$504,A9))) -> 0.96400457 | AR9: =IF(AO9<0,EXP(SUMIFS(Daily!$Q$2:$Q$504,Daily!$B$2:$B$504,A9)),1+D9) -> 1.0009686 | AS9: =AM9*AP9+AN9*AQ9+AO9*AR9 -> 0.94742189 | AT9: =AM9*AP9/AS9 -> 0.81210556 | AU9: =AN9*AQ9/AS9 -> 0.61050177 | AV9: =ABS(AM9-0) -> 0.8 | AW9: =ABS(AN9-0) -> 0.6 | AX9: =AV9+AW9 -> 1.4 | AY9: =Inputs!$B$4*AV9+Inputs!$B$5*AW9 -> 0.001 | AZ9: =(1-AY9)*AS9-1 -> -0.053525533 | BA9: =AZ9-D9 -> -0.05403746
A10: 2016-09 | B10: =MATCH(C10,Inputs!$D$2:$D$3,0) -> 1 | C10: =VALUE(LEFT(A10,4)) -> 2016 | D10: =EXP(SUMIFS(Daily!$L$2:$L$504,Daily!$B$2:$B$504,A10))-1 -> 0.00050393895 | E10: =EXP(SUMIFS(Daily!$J$2:$J$504,Daily!$B$2:$B$504,A10))-EXP(SUMIFS(Daily!$L$2:$L$504,Daily!$B$2:$B$504,A10)) -> 0.010664273 | F10: =SUMIFS(Daily!$H$2:$H$504,Daily!$B$2:$B$504,A10) -> 0.0025713485 | G10: =1/F10 -> 388.90099 | H10: =E11 -> -0.079070467 | I10: =H10*G10 -> -30.750583 | J10: =STDEV(H$2:H9)/STDEV(I$2:I9) -> 0.0017081034 | K10: =EXP(SUMIFS(Daily!$K$2:$K$504,Daily!$B$2:$B$504,A10))-EXP(SUMIFS(Daily!$L$2:$L$504,Daily!$B$2:$B$504,A10)) -> -0.030535872 | L10: =SUMIFS(Daily!$I$2:$I$504,Daily!$B$2:$B$504,A10) -> 0.0025906542 | M10: =1/L10 -> 386.00289 | N10: =K11 -> 0.026435974 | O10: =N10*M10 -> 10.204362 | P10: =STDEV(N$2:N9)/STDEV(O$2:O9) -> 0.0024217553 | Q10: =B11 -> 1 | R10: =IF(Q10=1,F10,L10) -> 0.0025713485 | S10: =IF(Q10=1,G10,M10) -> 388.90099 | T10: =IF(Q10=1,J10,P10) -> 0.0017081034 | U10: =T10*S10 -> 0.66428309 | V10: =MIN(Inputs!$B$2,MAX(0,U10)) -> 0.66428309 | W10: =V9 -> 0.87244238 | X10: =W10*INDEX(Inputs!$E$2:$E$3,B10) -> 0.6979539 | Y10: =W10*INDEX(Inputs!$F$2:$F$3,B10) -> 0.52346543 | Z10: =1-X10-Y10 -> -0.22141933 | AA10: =IF(X10<0,EXP(SUMIFS(Daily!$O$2:$O$504,Daily!$B$2:$B$504,A10)),EXP(SUMIFS(Daily!$M$2:$M$504,Daily!$B$2:$B$504,A10))) -> 1.0278504 | AB10: =IF(Y10<0,EXP(SUMIFS(Daily!$P$2:$P$504,Daily!$B$2:$B$504,A10)),EXP(SUMIFS(Daily!$N$2:$N$504,Daily!$B$2:$B$504,A10))) -> 0.98202666 | AC10: =IF(Z10<0,EXP(SUMIFS(Daily!$Q$2:$Q$504,Daily!$B$2:$B$504,A10)),1+D10) -> 1.0009209 | AD10: =X10*AA10+Y10*AB10+Z10*AC10 -> 1.009826 | AE10: =X10*AA10/AD10 -> 0.71041172 | AF10: =Y10*AB10/AD10 -> 0.50905503 | AG10: =ABS(X10-AE9) -> 0.37599263 | AH10: =ABS(Y10-AF9) -> 0.28387575 | AI10: =AG10+AH10 -> 0.65986838 | AJ10: =Inputs!$B$4*AG10+Inputs!$B$5*AH10 -> 0.00047187207 | AK10: =(1-AJ10)*AD10-1 -> 0.0093494913 | AL10: =AK10-D10 -> 0.0088455523 | AM10: =1*INDEX(Inputs!$E$2:$E$3,B10) -> 0.8 | AN10: =1*INDEX(Inputs!$F$2:$F$3,B10) -> 0.6 | AO10: =1-AM10-AN10 -> -0.4 | AP10: =IF(AM10<0,EXP(SUMIFS(Daily!$O$2:$O$504,Daily!$B$2:$B$504,A10)),EXP(SUMIFS(Daily!$M$2:$M$504,Daily!$B$2:$B$504,A10))) -> 1.0278504 | AQ10: =IF(AN10<0,EXP(SUMIFS(Daily!$P$2:$P$504,Daily!$B$2:$B$504,A10)),EXP(SUMIFS(Daily!$N$2:$N$504,Daily!$B$2:$B$504,A10))) -> 0.98202666 | AR10: =IF(AO10<0,EXP(SUMIFS(Daily!$Q$2:$Q$504,Daily!$B$2:$B$504,A10)),1+D10) -> 1.0009209 | AS10: =AM10*AP10+AN10*AQ10+AO10*AR10 -> 1.011128 | AT10: =AM10*AP10/AS10 -> 0.81323072 | AU10: =AN10*AQ10/AS10 -> 0.58273137 | AV10: =ABS(AM10-AT9) -> 0.012105561 | AW10: =ABS(AN10-AU9) -> 0.010501774 | AX10: =AV10+AW10 -> 0.022607335 | AY10: =Inputs!$B$4*AV10+Inputs!$B$5*AW10 -> 1.6554555e-05 | AZ10: =(1-AY10)*AS10-1 -> 0.011111255 | BA10: =AZ10-D10 -> 0.010607316
A11: 2016-10 | B11: =MATCH(C11,Inputs!$D$2:$D$3,0) -> 1 | C11: =VALUE(LEFT(A11,4)) -> 2016 | D11: =EXP(SUMIFS(Daily!$L$2:$L$504,Daily!$B$2:$B$504,A11))-1 -> 0.00053881682 | E11: =EXP(SUMIFS(Daily!$J$2:$J$504,Daily!$B$2:$B$504,A11))-EXP(SUMIFS(Daily!$L$2:$L$504,Daily!$B$2:$B$504,A11)) -> -0.079070467 | F11: =SUMIFS(Daily!$H$2:$H$504,Daily!$B$2:$B$504,A11) -> 0.0013586175 | G11: =1/F11 -> 736.04232 | H11: =E12 -> -0.020155606 | I11: =H11*G11 -> -14.835379 | J11: =STDEV(H$2:H10)/STDEV(I$2:I10) -> 0.0019348771 | K11: =EXP(SUMIFS(Daily!$K$2:$K$504,Daily!$B$2:$B$504,A11))-EXP(SUMIFS(Daily!$L$2:$L$504,Daily!$B$2:$B$504,A11)) -> 0.026435974 | L11: =SUMIFS(Daily!$I$2:$I$504,Daily!$B$2:$B$504,A11) -> 0.0021344749 | M11: =1/L11 -> 468.49929 | N11: =K12 -> 0.02434824 | O11: =N11*M11 -> 11.407133 | P11: =STDEV(N$2:N10)/STDEV(O$2:O10) -> 0.0024385569 | Q11: =B12 -> 1 | R11: =IF(Q11=1,F11,L11) -> 0.0013586175 | S11: =IF(Q11=1,G11,M11) -> 736.04232 | T11: =IF(Q11=1,J11,P11) -> 0.0019348771 | U11: =T11*S11 -> 1.4241514 | V11: =MIN(Inputs!$B$2,MAX(0,U11)) -> 1.3 | W11: =V10 -> 0.66428309 | X11: =W11*INDEX(Inputs!$E$2:$E$3,B11) -> 0.53142647 | Y11: =W11*INDEX(Inputs!$F$2:$F$3,B11) -> 0.39856986 | Z11: =1-X11-Y11 -> 0.07000367 | AA11: =IF(X11<0,EXP(SUMIFS(Daily!$O$2:$O$504,Daily!$B$2:$B$504,A11)),EXP(SUMIFS(Daily!$M$2:$M$504,Daily!$B$2:$B$504,A11))) -> 0.90409561 | AB11: =IF(Y11<0,EXP(SUMIFS(Daily!$P$2:$P$504,Daily!$B$2:$B$504,A11)),EXP(SUMIFS(Daily!$N$2:$N$504,Daily!$B$2:$B$504,A11))) -> 0.99755822 | AC11: =IF(Z11<0,EXP(SUMIFS(Daily!$Q$2:$Q$504,Daily!$B$2:$B$504,A11)),1+D11) -> 1.0005388 | AD11: =X11*AA11+Y11*AB11+Z11*AC11 -> 0.94809837 | AE11: =X11*AA11/AD11 -> 0.50676212 | AF11: =Y11*AB11/AD11 -> 0.41936222 | AG11: =ABS(X11-AE10) -> 0.17898525 | AH11: =ABS(Y11-AF10) -> 0.11048518 | AI11: =AG11+AH11 -> 0.28947042 | AJ11: =Inputs!$B$4*AG11+Inputs!$B$5*AH11 -> 0.0001999778 | AK11: =(1-AJ11)*AD11-1 -> -0.052091231 | AL11: =AK11-D11 -> -0.052630048 | AM11: =1*INDEX(Inputs!$E$2:$E$3,B11) -> 0.8 | AN11: =1*INDEX(Inputs!$F$2:$F$3,B11) -> 0.6 | AO11: =1-AM11-AN11 -> -0.4 | AP11: =IF(AM11<0,EXP(SUMIFS(Daily!$O$2:$O$504,Daily!$B$2:$B$504,A11)),EXP(SUMIFS(Daily!$M$2:$M$504,Daily!$B$2:$B$504,A11))) -> 0.90409561 | AQ11: =IF(AN11<0,EXP(SUMIFS(Daily!$P$2:$P$504,Daily!$B$2:$B$504,A11)),EXP(SUMIFS(Daily!$N$2:$N$504,Daily!$B$2:$B$504,A11))) -> 0.99755822 | AR11: =IF(AO11<0,EXP(SUMIFS(Daily!$Q$2:$Q$504,Daily!$B$2:$B$504,A11)),1+D11) -> 1.0009558 | AS11: =AM11*AP11+AN11*AQ11+AO11*AR11 -> 0.92142911 | AT11: =AM11*AP11/AS11 -> 0.78495077 | AU11: =AN11*AQ11/AS11 -> 0.64957242 | AV11: =ABS(AM11-AT10) -> 0.013230725 | AW11: =ABS(AN11-AU10) -> 0.017268633 | AX11: =AV11+AW11 -> 0.030499358 | AY11: =Inputs!$B$4*AV11+Inputs!$B$5*AW11 -> 2.3883996e-05 | AZ11: =(1-AY11)*AS11-1 -> -0.078592899 | BA11: =AZ11-D11 -> -0.079131716
A12: 2016-11 | B12: =MATCH(C12,Inputs!$D$2:$D$3,0) -> 1 | C12: =VALUE(LEFT(A12,4)) -> 2016 | D12: =EXP(SUMIFS(Daily!$L$2:$L$504,Daily!$B$2:$B$504,A12))-1 -> 0.00057369584 | E12: =EXP(SUMIFS(Daily!$J$2:$J$504,Daily!$B$2:$B$504,A12))-EXP(SUMIFS(Daily!$L$2:$L$504,Daily!$B$2:$B$504,A12)) -> -0.020155606 | F12: =SUMIFS(Daily!$H$2:$H$504,Daily!$B$2:$B$504,A12) -> 0.00077335323 | G12: =1/F12 -> 1293.0702 | H12: =E13 -> 0.068308361 | I12: =H12*G12 -> 88.327505 | J12: =STDEV(H$2:H11)/STDEV(I$2:I11) -> 0.0019255356 | K12: =EXP(SUMIFS(Daily!$K$2:$K$504,Daily!$B$2:$B$504,A12))-EXP(SUMIFS(Daily!$L$2:$L$504,Daily!$B$2:$B$504,A12)) -> 0.02434824 | L12: =SUMIFS(Daily!$I$2:$I$504,Daily!$B$2:$B$504,A12) -> 0.0020125972 | M12: =1/L12 -> 496.87042 | N12: =K13 -> 0.052697718 | O12: =N12*M12 -> 26.183937 | P12: =STDEV(N$2:N11)/STDEV(O$2:O11) -> 0.0024176134 | Q12: =B13 -> 1 | R12: =IF(Q12=1,F12,L12) -> 0.00077335323 | S12: =IF(Q12=1,G12,M12) -> 1293.0702 | T12: =IF(Q12=1,J12,P12) -> 0.0019255356 | U12: =T12*S12 -> 2.4898526 | V12: =MIN(Inputs!$B$2,MAX(0,U12)) -> 1.3 | W12: =V11 -> 1.3 | X12: =W12*INDEX(Inputs!$E$2:$E$3,B12) -> 1.04 | Y12: =W12*INDEX(Inputs!$F$2:$F$3,B12) -> 0.78 | Z12: =1-X12-Y12 -> -0.82 | AA12: =IF(X12<0,EXP(SUMIFS(Daily!$O$2:$O$504,Daily!$B$2:$B$504,A12)),EXP(SUMIFS(Daily!$M$2:$M$504,Daily!$B$2:$B$504,A12))) -> 0.96636075 | AB12: =IF(Y12<0,EXP(SUMIFS(Daily!$P$2:$P$504,Daily!$B$2:$B$504,A12)),EXP(SUMIFS(Daily!$N$2:$N$504,Daily!$B$2:$B$504,A12))) -> 1.0124138 | AC12: =IF(Z12<0,EXP(SUMIFS(Daily!$Q$2:$Q$504,Daily!$B$2:$B$504,A12)),1+D12) -> 1.0009907 | AD12: =X12*AA12+Y12*AB12+Z12*AC12 -> 0.97388562 | AE12: =X12*AA12/AD12 -> 1.0319643 | AF12: =Y12*AB12/AD12 -> 0.81085784 | AG12: =ABS(X12-AE11) -> 0.53323788 | AH12: =ABS(Y12-AF11) -> 0.36063778 | AI12: =AG12+AH12 -> 0.89387566 | AJ12: =Inputs!$B$4*AG12+Inputs!$B$5*AH12 -> 0.00062725672 | AK12: =(1-AJ12)*AD12-1 -> -0.026725258 | AL12: =AK12-D12 -> -0.027298954 | AM12: =1*INDEX(Inputs!$E$2:$E$3,B12) -> 0.8 | AN12: =1*INDEX(Inputs!$F$2:$F$3,B12) -> 0.6 | AO12: =1-AM12-AN12 -> -0.4 | AP12: =IF(AM12<0,EXP(SUMIFS(Daily!$O$2:$O$504,Daily!$B$2:$B$504,A12)),EXP(SUMIFS(Daily!$M$2:$M$504,Daily!$B$2:$B$504,A12))) -> 0.96636075 | AQ12: =IF(AN12<0,EXP(SUMIFS(Daily!$P$2:$P$504,Daily!$B$2:$B$504,A12)),EXP(SUMIFS(Daily!$N$2:$N$504,Daily!$B$2:$B$504,A12))) -> 1.0124138 | AR12: =IF(AO12<0,EXP(SUMIFS(Daily!$Q$2:$Q$504,Daily!$B$2:$B$504,A12)),1+D12) -> 1.0009907 | AS12: =AM12*AP12+AN12*AQ12+AO12*AR12 -> 0.98014063 | AT12: =AM12*AP12/AS12 -> 0.78875273 | AU12: =AN12*AQ12/AS12 -> 0.61975627 | AV12: =ABS(AM12-AT11) -> 0.015049232 | AW12: =ABS(AN12-AU11) -> 0.049572419 | AX12: =AV12+AW12 -> 0.064621651 | AY12: =Inputs!$B$4*AV12+Inputs!$B$5*AW12 -> 5.7097035e-05 | AZ12: =(1-AY12)*AS12-1 -> -0.019915332 | BA12: =AZ12-D12 -> -0.020489028
A13: 2016-12 | B13: =MATCH(C13,Inputs!$D$2:$D$3,0) -> 1 | C13: =VALUE(LEFT(A13,4)) -> 2016 | D13: =EXP(SUMIFS(Daily!$L$2:$L$504,Daily!$B$2:$B$504,A13))-1 -> 0.00060857603 | E13: =EXP(SUMIFS(Daily!$J$2:$J$504,Daily!$B$2:$B$504,A13))-EXP(SUMIFS(Daily!$L$2:$L$504,Daily!$B$2:$B$504,A13)) -> 0.068308361 | F13: =SUMIFS(Daily!$H$2:$H$504,Daily!$B$2:$B$504,A13) -> 0.0013953215 | G13: =1/F13 -> 716.68073 | H13: =E14 -> 0.026221912 | I13: =H13*G13 -> 18.792739 | J13: =STDEV(H$2:H12)/STDEV(I$2:I12) -> 0.0014468991 | K13: =EXP(SUMIFS(Daily!$K$2:$K$504,Daily!$B$2:$B$504,A13))-EXP(SUMIFS(Daily!$L$2:$L$504,Daily!$B$2:$B$504,A13)) -> 0.052697718 | L13: =SUMIFS(Daily!$I$2:$I$504,Daily!$B$2:$B$504,A13) -> 0.0018336509 | M13: =1/L13 -> 545.36009 | N13: =K14 -> 0.006575221 | O13: =N13*M13 -> 3.5858631 | P13: =STDEV(N$2:N12)/STDEV(O$2:O12) -> 0.0023059144 | Q13: =B14 -> 2 | R13: =IF(Q13=1,F13,L13) -> 0.0018336509 | S13: =IF(Q13=1,G13,M13) -> 545.36009 | T13: =IF(Q13=1,J13,P13) -> 0.0023059144 | U13: =T13*S13 -> 1.2575537 | V13: =MIN(Inputs!$B$2,MAX(0,U13)) -> 1.2575537 | W13: =V12 -> 1.3 | X13: =W13*INDEX(Inputs!$E$2:$E$3,B13) -> 1.04 | Y13: =W13*INDEX(Inputs!$F$2:$F$3,B13) -> 0.78 | Z13: =1-X13-Y13 -> -0.82 | AA13: =IF(X13<0,EXP(SUMIFS(Daily!$O$2:$O$504,Daily!$B$2:$B$504,A13)),EXP(SUMIFS(Daily!$M$2:$M$504,Daily!$B$2:$B$504,A13))) -> 1.0433433 | AB13: =IF(Y13<0,EXP(SUMIFS(Daily!$P$2:$P$504,Daily!$B$2:$B$504,A13)),EXP(SUMIFS(Daily!$N$2:$N$504,Daily!$B$2:$B$504,A13))) -> 1.0557994 | AC13: =IF(Z13<0,EXP(SUMIFS(Daily!$Q$2:$Q$504,Daily!$B$2:$B$504,A13)),1+D13) -> 1.0010256 | AD13: =X13*AA13+Y13*AB13+Z13*AC13 -> 1.0877595 | AE13: =X13*AA13/AD13 -> 0.99753389 | AF13: =Y13*AB13/AD13 -> 0.75708232 | AG13: =ABS(X13-AE12) -> 0.0080357092 | AH13: =ABS(Y13-AF12) -> 0.03085784 | AI13: =AG13+AH13 -> 0.038893549 | AJ13: =Inputs!$B$4*AG13+Inputs!$B$5*AH13 -> 3.4875694e-05 | AK13: =(1-AJ13)*AD13-1 -> 0.087721582 | AL13: =AK13-D13 -> 0.087113006 | AM13: =1*INDEX(Inputs!$E$2:$E$3,B13) -> 0.8 | AN13: =1*INDEX(Inputs!$F$2:$F$3,B13) -> 0.6 | AO13: =1-AM13-AN13 -> -0.4 | AP13: =IF(AM13<0,EXP(SUMIFS(Daily!$O$2:$O$504,Daily!$B$2:$B$504,A13)),EXP(SUMIFS(Daily!$M$2:$M$504,Daily!$B$2:$B$504,A13))) -> 1.0433433 | AQ13: =IF(AN13<0,EXP(SUMIFS(Daily!$P$2:$P$504,Daily!$B$2:$B$504,A13)),EXP(SUMIFS(Daily!$N$2:$N$504,Daily!$B$2:$B$504,A13))) -> 1.0557994 | AR13: =IF(AO13<0,EXP(SUMIFS(Daily!$Q$2:$Q$504,Daily!$B$2:$B$504,A13)),1+D13) -> 1.0010256 | AS13: =AM13*AP13+AN13*AQ13+AO13*AR13 -> 1.067744 | AT13: =AM13*AP13/AS13 -> 0.78171791 | AU13: =AN13*AQ13/AS13 -> 0.59328792 | AV13: =ABS(AM13-AT12) -> 0.011247267 | AW13: =ABS(AN13-AU12) -> 0.019756267 | AX13: =AV13+AW13 -> 0.031003535 | AY13: =Inputs!$B$4*AV13+Inputs!$B$5*AW13 -> 2.5379901e-05 | AZ13: =(1-AY13)*AS13-1 -> 0.067716892 | BA13: =AZ13-D13 -> 0.067108316
A14: 2017-01 | B14: =MATCH(C14,Inputs!$D$2:$D$3,0) -> 2 | C14: =VALUE(LEFT(A14,4)) -> 2017 | D14: =EXP(SUMIFS(Daily!$L$2:$L$504,Daily!$B$2:$B$504,A14))-1 -> 0.00061201621 | E14: =EXP(SUMIFS(Daily!$J$2:$J$504,Daily!$B$2:$B$504,A14))-EXP(SUMIFS(Daily!$L$2:$L$504,Daily!$B$2:$B$504,A14)) -> 0.026221912 | F14: =SUMIFS(Daily!$H$2:$H$504,Daily!$B$2:$B$504,A14) -> 0.0010649903 | G14: =1/F14 -> 938.9757 | H14: =E15 -> 0.017160505 | I14: =H14*G14 -> 16.113297 | J14: =STDEV(H$2:H13)/STDEV(I$2:I13) -> 0.0014463992 | K14: =EXP(SUMIFS(Daily!$K$2:$K$504,Daily!$B$2:$B$504,A14))-EXP(SUMIFS(Daily!$L$2:$L$504,Daily!$B$2:$B$504,A14)) -> 0.006575221 | L14: =SUMIFS(Daily!$I$2:$I$504,Daily!$B$2:$B$504,A14) -> 0.0011760356 | M14: =1/L14 -> 850.31441 | N14: =K15 -> 0.053260233 | O14: =N14*M14 -> 45.287943 | P14: =STDEV(N$2:N13)/STDEV(O$2:O13) -> 0.0023063054 | Q14: =B15 -> 2 | R14: =IF(Q14=1,F14,L14) -> 0.0011760356 | S14: =IF(Q14=1,G14,M14) -> 850.31441 | T14: =IF(Q14=1,J14,P14) -> 0.0023063054 | U14: =T14*S14 -> 1.9610847 | V14: =MIN(Inputs!$B$2,MAX(0,U14)) -> 1.3 | W14: =V13 -> 1.2575537 | X14: =W14*INDEX(Inputs!$E$2:$E$3,B14) -> -0.37726611 | Y14: =W14*INDEX(Inputs!$F$2:$F$3,B14) -> 1.5090645 | Z14: =1-X14-Y14 -> -0.13179834 | AA14: =IF(X14<0,EXP(SUMIFS(Daily!$O$2:$O$504,Daily!$B$2:$B$504,A14)),EXP(SUMIFS(Daily!$M$2:$M$504,Daily!$B$2:$B$504,A14))) -> 1.0244043 | AB14: =IF(Y14<0,EXP(SUMIFS(Daily!$P$2:$P$504,Daily!$B$2:$B$504,A14)),EXP(SUMIFS(Daily!$N$2:$N$504,Daily!$B$2:$B$504,A14))) -> 1.0123111 | AC14: =IF(Z14<0,EXP(SUMIFS(Daily!$Q$2:$Q$504,Daily!$B$2:$B$504,A14)),1+D14) -> 1.0010091 | AD14: =X14*AA14+Y14*AB14+Z14*AC14 -> 1.0092383 | AE14: =X14*AA14/AD14 -> -0.38293537 | AF14: =Y14*AB14/AD14 -> 1.5136591 | AG14: =ABS(X14-AE13) -> 1.3748 | AH14: =ABS(Y14-AF13) -> 0.75198214 | AI14: =AG14+AH14 -> 2.1267821 | AJ14: =Inputs!$B$4*AG14+Inputs!$B$5*AH14 -> 0.0014393821 | AK14: =(1-AJ14)*AD14-1 -> 0.0077855944 | AL14: =AK14-D14 -> 0.0071735782 | AM14: =1*INDEX(Inputs!$E$2:$E$3,B14) -> -0.3 | AN14: =1*INDEX(Inputs!$F$2:$F$3,B14) -> 1.2 | AO14: =1-AM14-AN14 -> 0.1 | AP14: =IF(AM14<0,EXP(SUMIFS(Daily!$O$2:$O$504,Daily!$B$2:$B$504,A14)),EXP(SUMIFS(Daily!$M$2:$M$504,Daily!$B$2:$B$504,A14))) -> 1.0244043 | AQ14: =IF(AN14<0,EXP(SUMIFS(Daily!$P$2:$P$504,Daily!$B$2:$B$504,A14)),EXP(SUMIFS(Daily!$N$2:$N$504,Daily!$B$2:$B$504,A14))) -> 1.0123111 | AR14: =IF(AO14<0,EXP(SUMIFS(Daily!$Q$2:$Q$504,Daily!$B$2:$B$504,A14)),1+D14) -> 1.000612 | AS14: =AM14*AP14+AN14*AQ14+AO14*AR14 -> 1.0075132 | AT14: =AM14*AP14/AS14 -> -0.30502954 | AU14: =AN14*AQ14/AS14 -> 1.2057145 | AV14: =ABS(AM14-AT13) -> 1.0817179 | AW14: =ABS(AN14-AU13) -> 0.60671208 | AX14: =AV14+AW14 -> 1.68843 | AY14: =Inputs!$B$4*AV14+Inputs!$B$5*AW14 -> 0.001147571 | AZ14: =(1-AY14)*AS14-1 -> 0.0063569988 | BA14: =AZ14-D14 -> 0.0057449826
A15: 2017-02 | B15: =MATCH(C15,Inputs!$D$2:$D$3,0) -> 2 | C15: =VALUE(LEFT(A15,4)) -> 2017 | D15: =EXP(SUMIFS(Daily!$L$2:$L$504,Daily!$B$2:$B$504,A15))-1 -> 0.00061071065 | E15: =EXP(SUMIFS(Daily!$J$2:$J$504,Daily!$B$2:$B$504,A15))-EXP(SUMIFS(Daily!$L$2:$L$504,Daily!$B$2:$B$504,A15)) -> 0.017160505 | F15: =SUMIFS(Daily!$H$2:$H$504,Daily!$B$2:$B$504,A15) -> 0.00064245072 | G15: =1/F15 -> 1556.5396 | H15: =E16 -> -0.011627308 | I15: =H15*G15 -> -18.098366 | J15: =STDEV(H$2:H14)/STDEV(I$2:I14) -> 0.0014449542 | K15: =EXP(SUMIFS(Daily!$K$2:$K$504,Daily!$B$2:$B$504,A15))-EXP(SUMIFS(Daily!$L$2:$L$504,Daily!$B$2:$B$504,A15)) -> 0.053260233 | L15: =SUMIFS(Daily!$I$2:$I$504,Daily!$B$2:$B$504,A15) -> 0.0011060291 | M15: =1/L15 -> 904.13532 | N15: =K16 -> 0.0046792001 | O15: =N15*M15 -> 4.23063 | P15: =STDEV(N$2:N14)/STDEV(O$2:O14) -> 0.0018489474 | Q15: =B16 -> 2 | R15: =IF(Q15=1,F15,L15) -> 0.0011060291 | S15: =IF(Q15=1,G15,M15) -> 904.13532 | T15: =IF(Q15=1,J15,P15) -> 0.0018489474 | U15: =T15*S15 -> 1.6716987 | V15: =MIN(Inputs!$B$2,MAX(0,U15)) -> 1.3 | W15: =V14 -> 1.3 | X15: =W15*INDEX(Inputs!$E$2:$E$3,B15) -> -0.39 | Y15: =W15*INDEX(Inputs!$F$2:$F$3,B15) -> 1.56 | Z15: =1-X15-Y15 -> -0.17 | AA15: =IF(X15<0,EXP(SUMIFS(Daily!$O$2:$O$504,Daily!$B$2:$B$504,A15)),EXP(SUMIFS(Daily!$M$2:$M$504,Daily!$B$2:$B$504,A15))) -> 0.99105137 | AB15: =IF(Y15<0,EXP(SUMIFS(Daily!$P$2:$P$504,Daily!$B$2:$B$504,A15)),EXP(SUMIFS(Daily!$N$2:$N$504,Daily!$B$2:$B$504,A15))) -> 1.0425124 | AC15: =IF(Z15<0,EXP(SUMIFS(Daily!$Q$2:$Q$504,Daily!$B$2:$B$504,A15)),1+D15) -> 1.000988 | AD15: =X15*AA15+Y15*AB15+Z15*AC15 -> 1.0696413 | AE15: =X15*AA15/AD15 -> -0.36134547 | AF15: =Y15*AB15/AD15 -> 1.5204343 | AG15: =ABS(X15-AE14) -> 0.0070646321 | AH15: =ABS(Y15-AF14) -> 0.046340945 | AI15: =AG15+AH15 -> 0.053405577 | AJ15: =Inputs!$B$4*AG15+Inputs!$B$5*AH15 -> 4.9873261e-05 | AK15: =(1-AJ15)*AD15-1 -> 0.069587934 | AL15: =AK15-D15 -> 0.068977223 | AM15: =1*INDEX(Inputs!$E$2:$E$3,B15) -> -0.3 | AN15: =1*INDEX(Inputs!$F$2:$F$3,B15) -> 1.2 | AO15: =1-AM15-AN15 -> 0.1 | AP15: =IF(AM15<0,EXP(SUMIFS(Daily!$O$2:$O$504,Daily!$B$2:$B$504,A15)),EXP(SUMIFS(Daily!$M$2:$M$504,Daily!$B$2:$B$504,A15))) -> 0.99105137 | AQ15: =IF(AN15<0,EXP(SUMIFS(Daily!$P$2:$P$504,Daily!$B$2:$B$504,A15)),EXP(SUMIFS(Daily!$N$2:$N$504,Daily!$B$2:$B$504,A15))) -> 1.0425124 | AR15: =IF(AO15<0,EXP(SUMIFS(Daily!$Q$2:$Q$504,Daily!$B$2:$B$504,A15)),1+D15) -> 1.0006107 | AS15: =AM15*AP15+AN15*AQ15+AO15*AR15 -> 1.0537605 | AT15: =AM15*AP15/AS15 -> -0.28214705 | AU15: =AN15*AQ15/AS15 -> 1.1871909 | AV15: =ABS(AM15-AT14) -> 0.005029544 | AW15: =ABS(AN15-AU14) -> 0.0057145152 | AX15: =AV15+AW15 -> 0.010744059 | AY15: =Inputs!$B$4*AV15+Inputs!$B$5*AW15 -> 8.2292872e-06 | AZ15: =(1-AY15)*AS15-1 -> 0.053751812 | BA15: =AZ15-D15 -> 0.053141102
A16: 2017-03 | B16: =MATCH(C16,Inputs!$D$2:$D$3,0) -> 2 | C16: =VALUE(LEFT(A16,4)) -> 2017 | D16: =EXP(SUMIFS(Daily!$L$2:$L$504,Daily!$B$2:$B$504,A16))-1 -> 0.00077753714 | E16: =EXP(SUMIFS(Daily!$J$2:$J$504,Daily!$B$2:$B$504,A16))-EXP(SUMIFS(Daily!$L$2:$L$504,Daily!$B$2:$B$504,A16)) -> -0.011627308 | F16: =SUMIFS(Daily!$H$2:$H$504,Daily!$B$2:$B$504,A16) -> 0.0015478089 | G16: =1/F16 -> 646.07461 | H16: =E17 -> -0.017370033 | I16: =H16*G16 -> -11.222337 | J16: =STDEV(H$2:H15)/STDEV(I$2:I15) -> 0.0014217116 | K16: =EXP(SUMIFS(Daily!$K$2:$K$504,Daily!$B$2:$B$504,A16))-EXP(SUMIFS(Daily!$L$2:$L$504,Daily!$B$2:$B$504,A16)) -> 0.0046792001 | L16: =SUMIFS(Daily!$I$2:$I$504,Daily!$B$2:$B$504,A16) -> 0.0010885623 | M16: =1/L16 -> 918.64288 | N16: =K17 -> 0.004816468 | O16: =N16*M16 -> 4.424614 | P16: =STDEV(N$2:N15)/STDEV(O$2:O15) -> 0.0018507308 | Q16: =B17 -> 2 | R16: =IF(Q16=1,F16,L16) -> 0.0010885623 | S16: =IF(Q16=1,G16,M16) -> 918.64288 | T16: =IF(Q16=1,J16,P16) -> 0.0018507308 | U16: =T16*S16 -> 1.7001606 | V16: =MIN(Inputs!$B$2,MAX(0,U16)) -> 1.3 | W16: =V15 -> 1.3 | X16: =W16*INDEX(Inputs!$E$2:$E$3,B16) -> -0.39 | Y16: =W16*INDEX(Inputs!$F$2:$F$3,B16) -> 1.56 | Z16: =1-X16-Y16 -> -0.17 | AA16: =IF(X16<0,EXP(SUMIFS(Daily!$O$2:$O$504,Daily!$B$2:$B$504,A16)),EXP(SUMIFS(Daily!$M$2:$M$504,Daily!$B$2:$B$504,A16))) -> 0.9860376 | AB16: =IF(Y16<0,EXP(SUMIFS(Daily!$P$2:$P$504,Daily!$B$2:$B$504,A16)),EXP(SUMIFS(Daily!$N$2:$N$504,Daily!$B$2:$B$504,A16))) -> 1.0011831 | AC16: =IF(Z16<0,EXP(SUMIFS(Daily!$Q$2:$Q$504,Daily!$B$2:$B$504,A16)),1+D16) -> 1.0012343 | AD16: =X16*AA16+Y16*AB16+Z16*AC16 -> 1.0070812 | AE16: =X16*AA16/AD16 -> -0.38185071 | AF16: =Y16*AB16/AD16 -> 1.5508637 | AG16: =ABS(X16-AE15) -> 0.028654526 | AH16: =ABS(Y16-AF15) -> 0.039565717 | AI16: =AG16+AH16 -> 0.068220243 | AJ16: =Inputs!$B$4*AG16+Inputs!$B$5*AH16 -> 5.389298e-05 | AK16: =(1-AJ16)*AD16-1 -> 0.0070268998 | AL16: =AK16-D16 -> 0.0062493627 | AM16: =1*INDEX(Inputs!$E$2:$E$3,B16) -> -0.3 | AN16: =1*INDEX(Inputs!$F$2:$F$3,B16) -> 1.2 | AO16: =1-AM16-AN16 -> 0.1 | AP16: =IF(AM16<0,EXP(SUMIFS(Daily!$O$2:$O$504,Daily!$B$2:$B$504,A16)),EXP(SUMIFS(Daily!$M$2:$M$504,Daily!$B$2:$B$504,A16))) -> 0.9860376 | AQ16: =IF(AN16<0,EXP(SUMIFS(Daily!$P$2:$P$504,Daily!$B$2:$B$504,A16)),EXP(SUMIFS(Daily!$N$2:$N$504,Daily!$B$2:$B$504,A16))) -> 1.0011831 | AR16: =IF(AO16<0,EXP(SUMIFS(Daily!$Q$2:$Q$504,Daily!$B$2:$B$504,A16)),1+D16) -> 1.0007775 | AS16: =AM16*AP16+AN16*AQ16+AO16*AR16 -> 1.0056862 | AT16: =AM16*AP16/AS16 -> -0.29413874 | AU16: =AN16*AQ16/AS16 -> 1.1946268 | AV16: =ABS(AM16-AT15) -> 0.01785295 | AW16: =ABS(AN16-AU15) -> 0.012809131 | AX16: =AV16+AW16 -> 0.03066208 | AY16: =Inputs!$B$4*AV16+Inputs!$B$5*AW16 -> 2.1735605e-05 | AZ16: =(1-AY16)*AS16-1 -> 0.0056643635 | BA16: =AZ16-D16 -> 0.0048868264
A17: 2017-04 | B17: =MATCH(C17,Inputs!$D$2:$D$3,0) -> 2 | C17: =VALUE(LEFT(A17,4)) -> 2017 | D17: =EXP(SUMIFS(Daily!$L$2:$L$504,Daily!$B$2:$B$504,A17))-1 -> 0.00067383004 | E17: =EXP(SUMIFS(Daily!$J$2:$J$504,Daily!$B$2:$B$504,A17))-EXP(SUMIFS(Daily!$L$2:$L$504,Daily!$B$2:$B$504,A17)) -> -0.017370033 | F17: =SUMIFS(Daily!$H$2:$H$504,Daily!$B$2:$B$504,A17) -> 0.000731331 | G17: =1/F17 -> 1367.3699 | H17: =E18 -> -0.011546821 | I17: =H17*G17 -> -15.788775 | J17: =STDEV(H$2:H16)/STDEV(I$2:I16) -> 0.0014244114 | K17: =EXP(SUMIFS(Daily!$K$2:$K$504,Daily!$B$2:$B$504,A17))-EXP(SUMIFS(Daily!$L$2:$L$504,Daily!$B$2:$B$504,A17)) -> 0.004816468 | L17: =SUMIFS(Daily!$I$2:$I$504,Daily!$B$2:$B$504,A17) -> 0.0012363591 | M17: =1/L17 -> 808.82652 | N17: =K18 -> 0.036912757 | O17: =N17*M17 -> 29.856017 | P17: =STDEV(N$2:N16)/STDEV(O$2:O16) -> 0.0018524136 | Q17: =B18 -> 2 | R17: =IF(Q17=1,F17,L17) -> 0.0012363591 | S17: =IF(Q17=1,G17,M17) -> 808.82652 | T17: =IF(Q17=1,J17,P17) -> 0.0018524136 | U17: =T17*S17 -> 1.4982812 | V17: =MIN(Inputs!$B$2,MAX(0,U17)) -> 1.3 | W17: =V16 -> 1.3 | X17: =W17*INDEX(Inputs!$E$2:$E$3,B17) -> -0.39 | Y17: =W17*INDEX(Inputs!$F$2:$F$3,B17) -> 1.56 | Z17: =1-X17-Y17 -> -0.17 | AA17: =IF(X17<0,EXP(SUMIFS(Daily!$O$2:$O$504,Daily!$B$2:$B$504,A17)),EXP(SUMIFS(Daily!$M$2:$M$504,Daily!$B$2:$B$504,A17))) -> 0.97966083 | AB17: =IF(Y17<0,EXP(SUMIFS(Daily!$P$2:$P$504,Daily!$B$2:$B$504,A17)),EXP(SUMIFS(Daily!$N$2:$N$504,Daily!$B$2:$B$504,A17))) -> 0.9996127 | AC17: =IF(Z17<0,EXP(SUMIFS(Daily!$Q$2:$Q$504,Daily!$B$2:$B$504,A17)),1+D17) -> 1.0010511 | AD17: =X17*AA17+Y17*AB17+Z17*AC17 -> 1.0071494 | AE17: =X17*AA17/AD17 -> -0.37935556 | AF17: =Y17*AB17/AD17 -> 1.5483262 | AG17: =ABS(X17-AE16) -> 0.0081492859 | AH17: =ABS(Y17-AF16) -> 0.0091362613 | AI17: =AG17+AH17 -> 0.017285547 | AJ17: =Inputs!$B$4*AG17+Inputs!$B$5*AH17 -> 1.3210904e-05 | AK17: =(1-AJ17)*AD17-1 -> 0.0071360924 | AL17: =AK17-D17 -> 0.0064622624 | AM17: =1*INDEX(Inputs!$E$2:$E$3,B17) -> -0.3 | AN17: =1*INDEX(Inputs!$F$2:$F$3,B17) -> 1.2 | AO17: =1-AM17-AN17 -> 0.1 | AP17: =IF(AM17<0,EXP(SUMIFS(Daily!$O$2:$O$504,Daily!$B$2:$B$504,A17)),EXP(SUMIFS(Daily!$M$2:$M$504,Daily!$B$2:$B$504,A17))) -> 0.97966083 | AQ17: =IF(AN17<0,EXP(SUMIFS(Daily!$P$2:$P$504,Daily!$B$2:$B$504,A17)),EXP(SUMIFS(Daily!$N$2:$N$504,Daily!$B$2:$B$504,A17))) -> 0.9996127 | AR17: =IF(AO17<0,EXP(SUMIFS(Daily!$Q$2:$Q$504,Daily!$B$2:$B$504,A17)),1+D17) -> 1.0006738 | AS17: =AM17*AP17+AN17*AQ17+AO17*AR17 -> 1.0057044 | AT17: =AM17*AP17/AS17 -> -0.29223125 | AU17: =AN17*AQ17/AS17 -> 1.1927315 | AV17: =ABS(AM17-AT16) -> 0.0058612572 | AW17: =ABS(AN17-AU16) -> 0.005373164 | AX17: =AV17+AW17 -> 0.011234421 | AY17: =Inputs!$B$4*AV17+Inputs!$B$5*AW17 -> 8.3037926e-06 | AZ17: =(1-AY17)*AS17-1 -> 0.005696023 | BA17: =AZ17-D17 -> 0.005022193
A18: 2017-05 | B18: =MATCH(C18,Inputs!$D$2:$D$3,0) -> 2 | C18: =VALUE(LEFT(A18,4)) -> 2017 | D18: =EXP(SUMIFS(Daily!$L$2:$L$504,Daily!$B$2:$B$504,A18))-1 -> 0.00081594396 | E18: =EXP(SUMIFS(Daily!$J$2:$J$504,Daily!$B$2:$B$504,A18))-EXP(SUMIFS(Daily!$L$2:$L$504,Daily!$B$2:$B$504,A18)) -> -0.011546821 | F18: =SUMIFS(Daily!$H$2:$H$504,Daily!$B$2:$B$504,A18) -> 0.0020217777 | G18: =1/F18 -> 494.61421 | H18: =E19 -> 0.0062684854 | I18: =H18*G18 -> 3.100482 | J18: =STDEV(H$2:H17)/STDEV(I$2:I17) -> 0.0014118704 | K18: =EXP(SUMIFS(Daily!$K$2:$K$504,Daily!$B$2:$B$504,A18))-EXP(SUMIFS(Daily!$L$2:$L$504,Daily!$B$2:$B$504,A18)) -> 0.036912757 | L18: =SUMIFS(Daily!$I$2:$I$504,Daily!$B$2:$B$504,A18) -> 0.00065240478 | M18: =1/L18 -> 1532.7907 | N18: =K19 -> -0.048172535 | O18: =N18*M18 -> -73.838415 | P18: =STDEV(N$2:N17)/STDEV(O$2:O17) -> 0.0017772395 | Q18: =B19 -> 2 | R18: =IF(Q18=1,F18,L18) -> 0.00065240478 | S18: =IF(Q18=1,G18,M18) -> 1532.7907 | T18: =IF(Q18=1,J18,P18) -> 0.0017772395 | U18: =T18*S18 -> 2.7241362 | V18: =MIN(Inputs!$B$2,MAX(0,U18)) -> 1.3 | W18: =V17 -> 1.3 | X18: =W18*INDEX(Inputs!$E$2:$E$3,B18) -> -0.39 | Y18: =W18*INDEX(Inputs!$F$2:$F$3,B18) -> 1.56 | Z18: =1-X18-Y18 -> -0.17 | AA18: =IF(X18<0,EXP(SUMIFS(Daily!$O$2:$O$504,Daily!$B$2:$B$504,A18)),EXP(SUMIFS(Daily!$M$2:$M$504,Daily!$B$2:$B$504,A18))) -> 0.96996518 | AB18: =IF(Y18<0,EXP(SUMIFS(Daily!$P$2:$P$504,Daily!$B$2:$B$504,A18)),EXP(SUMIFS(Daily!$N$2:$N$504,Daily!$B$2:$B$504,A18))) -> 1.0236955 | AC18: =IF(Z18<0,EXP(SUMIFS(Daily!$Q$2:$Q$504,Daily!$B$2:$B$504,A18)),1+D18) -> 1.0012529 | AD18: =X18*AA18+Y18*AB18+Z18*AC18 -> 1.0484656 | AE18: =X18*AA18/AD18 -> -0.36080002 | AF18: =Y18*AB18/AD18 -> 1.5231449 | AG18: =ABS(X18-AE17) -> 0.01064444 | AH18: =ABS(Y18-AF17) -> 0.011673788 | AI18: =AG18+AH18 -> 0.022318228 | AJ18: =Inputs!$B$4*AG18+Inputs!$B$5*AH18 -> 1.6996008e-05 | AK18: =(1-AJ18)*AD18-1 -> 0.048447816 | AL18: =AK18-D18 -> 0.047631872 | AM18: =1*INDEX(Inputs!$E$2:$E$3,B18) -> -0.3 | AN18: =1*INDEX(Inputs!$F$2:$F$3,B18) -> 1.2 | AO18: =1-AM18-AN18 -> 0.1 | AP18: =IF(AM18<0,EXP(SUMIFS(Daily!$O$2:$O$504,Daily!$B$2:$B$504,A18)),EXP(SUMIFS(Daily!$M$2:$M$504,Daily!$B$2:$B$504,A18))) -> 0.96996518 | AQ18: =IF(AN18<0,EXP(SUMIFS(Daily!$P$2:$P$504,Daily!$B$2:$B$504,A18)),EXP(SUMIFS(Daily!$N$2:$N$504,Daily!$B$2:$B$504,A18))) -> 1.0236955 | AR18: =IF(AO18<0,EXP(SUMIFS(Daily!$Q$2:$Q$504,Daily!$B$2:$B$504,A18)),1+D18) -> 1.0008159 | AS18: =AM18*AP18+AN18*AQ18+AO18*AR18 -> 1.0375267 | AT18: =AM18*AP18/AS18 -> -0.28046464 | AU18: =AN18*AQ18/AS18 -> 1.1840029 | AV18: =ABS(AM18-AT17) -> 0.0077687476 | AW18: =ABS(AN18-AU17) -> 0.0072685465 | AX18: =AV18+AW18 -> 0.015037294 | AY18: =Inputs!$B$4*AV18+Inputs!$B$5*AW18 -> 1.115292e-05 | AZ18: =(1-AY18)*AS18-1 -> 0.037515119 | BA18: =AZ18-D18 -> 0.036699175
A19: 2017-06 | B19: =MATCH(C19,Inputs!$D$2:$D$3,0) -> 2 | C19: =VALUE(LEFT(A19,4)) -> 2017 | D19: =EXP(SUMIFS(Daily!$L$2:$L$504,Daily!$B$2:$B$504,A19))-1 -> 0.00085423412 | E19: =EXP(SUMIFS(Daily!$J$2:$J$504,Daily!$B$2:$B$504,A19))-EXP(SUMIFS(Daily!$L$2:$L$504,Daily!$B$2:$B$504,A19)) -> 0.0062684854 | F19: =SUMIFS(Daily!$H$2:$H$504,Daily!$B$2:$B$504,A19) -> 0.0031000361 | G19: =1/F19 -> 322.57689 | H19: =E20 -> -0.0052368488 | I19: =H19*G19 -> -1.6892864 | J19: =STDEV(H$2:H18)/STDEV(I$2:I18) -> 0.001411761 | K19: =EXP(SUMIFS(Daily!$K$2:$K$504,Daily!$B$2:$B$504,A19))-EXP(SUMIFS(Daily!$L$2:$L$504,Daily!$B$2:$B$504,A19)) -> -0.048172535 | L19: =SUMIFS(Daily!$I$2:$I$504,Daily!$B$2:$B$504,A19) -> 0.0012618529 | M19: =1/L19 -> 792.4854 | N19: =K20 -> 0.013918989 | O19: =N19*M19 -> 11.030596 | P19: =STDEV(N$2:N18)/STDEV(O$2:O18) -> 0.0012398216 | Q19: =B20 -> 2 | R19: =IF(Q19=1,F19,L19) -> 0.0012618529 | S19: =IF(Q19=1,G19,M19) -> 792.4854 | T19: =IF(Q19=1,J19,P19) -> 0.0012398216 | U19: =T19*S19 -> 0.98254055 | V19: =MIN(Inputs!$B$2,MAX(0,U19)) -> 0.98254055 | W19: =V18 -> 1.3 | X19: =W19*INDEX(Inputs!$E$2:$E$3,B19) -> -0.39 | Y19: =W19*INDEX(Inputs!$F$2:$F$3,B19) -> 1.56 | Z19: =1-X19-Y19 -> -0.17 | AA19: =IF(X19<0,EXP(SUMIFS(Daily!$O$2:$O$504,Daily!$B$2:$B$504,A19)),EXP(SUMIFS(Daily!$M$2:$M$504,Daily!$B$2:$B$504,A19))) -> 1.0334584 | AB19: =IF(Y19<0,EXP(SUMIFS(Daily!$P$2:$P$504,Daily!$B$2:$B$504,A19)),EXP(SUMIFS(Daily!$N$2:$N$504,Daily!$B$2:$B$504,A19))) -> 0.96884426 | AC19: =IF(Z19<0,EXP(SUMIFS(Daily!$Q$2:$Q$504,Daily!$B$2:$B$504,A19)),1+D19) -> 1.0012912 | AD19: =X19*AA19+Y19*AB19+Z19*AC19 -> 0.93812876 | AE19: =X19*AA19/AD19 -> -0.42963056 | AF19: =Y19*AB19/AD19 -> 1.6110763 | AG19: =ABS(X19-AE18) -> 0.029199983 | AH19: =ABS(Y19-AF18) -> 0.036855139 | AI19: =AG19+AH19 -> 0.066055122 | AJ19: =Inputs!$B$4*AG19+Inputs!$B$5*AH19 -> 5.145513e-05 | AK19: =(1-AJ19)*AD19-1 -> -0.061919514 | AL19: =AK19-D19 -> -0.062773748 | AM19: =1*INDEX(Inputs!$E$2:$E$3,B19) -> -0.3 | AN19: =1*INDEX(Inputs!$F$2:$F$3,B19) -> 1.2 | AO19: =1-AM19-AN19 -> 0.1 | AP19: =IF(AM19<0,EXP(SUMIFS(Daily!$O$2:$O$504,Daily!$B$2:$B$504,A19)),EXP(SUMIFS(Daily!$M$2:$M$504,Daily!$B$2:$B$504,A19))) -> 1.0334584 | AQ19: =IF(AN19<0,EXP(SUMIFS(Daily!$P$2:$P$504,Daily!$B$2:$B$504,A19)),EXP(SUMIFS(Daily!$N$2:$N$504,Daily!$B$2:$B$504,A19))) -> 0.96884426 | AR19: =IF(AO19<0,EXP(SUMIFS(Daily!$Q$2:$Q$504,Daily!$B$2:$B$504,A19)),1+D19) -> 1.0008542 | AS19: =AM19*AP19+AN19*AQ19+AO19*AR19 -> 0.95266101 | AT19: =AM19*AP19/AS19 -> -0.32544371 | AU19: =AN19*AQ19/AS19 -> 1.2203849 | AV19: =ABS(AM19-AT18) -> 0.019535357 | AW19: =ABS(AN19-AU18) -> 0.015997063 | AX19: =AV19+AW19 -> 0.035532419 | AY19: =Inputs!$B$4*AV19+Inputs!$B$5*AW19 -> 2.5764741e-05 | AZ19: =(1-AY19)*AS19-1 -> -0.047363537 | BA19: =AZ19-D19 -> -0.048217772
A20: 2017-07 | B20: =MATCH(C20,Inputs!$D$2:$D$3,0) -> 2 | C20: =VALUE(LEFT(A20,4)) -> 2017 | D20: =EXP(SUMIFS(Daily!$L$2:$L$504,Daily!$B$2:$B$504,A20))-1 -> 0.00080977188 | E20: =EXP(SUMIFS(Daily!$J$2:$J$504,Daily!$B$2:$B$504,A20))-EXP(SUMIFS(Daily!$L$2:$L$504,Daily!$B$2:$B$504,A20)) -> -0.0052368488 | F20: =SUMIFS(Daily!$H$2:$H$504,Daily!$B$2:$B$504,A20) -> 0.0022449861 | G20: =1/F20 -> 445.43707 | H20: =E21 -> -0.055259682 | I20: =H20*G20 -> -24.614711 | J20: =STDEV(H$2:H19)/STDEV(I$2:I19) -> 0.0014140284 | K20: =EXP(SUMIFS(Daily!$K$2:$K$504,Daily!$B$2:$B$504,A20))-EXP(SUMIFS(Daily!$L$2:$L$504,Daily!$B$2:$B$504,A20)) -> 0.013918989 | L20: =SUMIFS(Daily!$I$2:$I$504,Daily!$B$2:$B$504,A20) -> 0.0023851428 | M20: =1/L20 -> 419.26211 | N20: =K21 -> 0.0061321739 | O20: =N20*M20 -> 2.5709882 | P20: =STDEV(N$2:N19)/STDEV(O$2:O19) -> 0.0012374902 | Q20: =B21 -> 2 | R20: =IF(Q20=1,F20,L20) -> 0.0023851428 | S20: =IF(Q20=1,G20,M20) -> 419.26211 | T20: =IF(Q20=1,J20,P20) -> 0.0012374902 | U20: =T20*S20 -> 0.51883274 | V20: =MIN(Inputs!$B$2,MAX(0,U20)) -> 0.51883274 | W20: =V19 -> 0.98254055 | X20: =W20*INDEX(Inputs!$E$2:$E$3,B20) -> -0.29476216 | Y20: =W20*INDEX(Inputs!$F$2:$F$3,B20) -> 1.1790487 | Z20: =1-X20-Y20 -> 0.11571351 | AA20: =IF(X20<0,EXP(SUMIFS(Daily!$O$2:$O$504,Daily!$B$2:$B$504,A20)),EXP(SUMIFS(Daily!$M$2:$M$504,Daily!$B$2:$B$504,A20))) -> 0.98703625 | AB20: =IF(Y20<0,EXP(SUMIFS(Daily!$P$2:$P$504,Daily!$B$2:$B$504,A20)),EXP(SUMIFS(Daily!$N$2:$N$504,Daily!$B$2:$B$504,A20))) -> 1.0097131 | AC20: =IF(Z20<0,EXP(SUMIFS(Daily!$Q$2:$Q$504,Daily!$B$2:$B$504,A20)),1+D20) -> 1.0008098 | AD20: =X20*AA20+Y20*AB20+Z20*AC20 -> 1.0153672 | AE20: =X20*AA20/AD20 -> -0.28653767 | AF20: =Y20*AB20/AD20 -> 1.1724832 | AG20: =ABS(X20-AE19) -> 0.1348684 | AH20: =ABS(Y20-AF19) -> 0.43202769 | AI20: =AG20+AH20 -> 0.56689609 | AJ20: =Inputs!$B$4*AG20+Inputs!$B$5*AH20 -> 0.00049946189 | AK20: =(1-AJ20)*AD20-1 -> 0.014860041 | AL20: =AK20-D20 -> 0.014050269 | AM20: =1*INDEX(Inputs!$E$2:$E$3,B20) -> -0.3 | AN20: =1*INDEX(Inputs!$F$2:$F$3,B20) -> 1.2 | AO20: =1-AM20-AN20 -> 0.1 | AP20: =IF(AM20<0,EXP(SUMIFS(Daily!$O$2:$O$504,Daily!$B$2:$B$504,A20)),EXP(SUMIFS(Daily!$M$2:$M$504,Daily!$B$2:$B$504,A20))) -> 0.98703625 | AQ20: =IF(AN20<0,EXP(SUMIFS(Daily!$P$2:$P$504,Daily!$B$2:$B$504,A20)),EXP(SUMIFS(Daily!$N$2:$N$504,Daily!$B$2:$B$504,A20))) -> 1.0097131 | AR20: =IF(AO20<0,EXP(SUMIFS(Daily!$Q$2:$Q$504,Daily!$B$2:$B$504,A20)),1+D20) -> 1.0008098 | AS20: =AM20*AP20+AN20*AQ20+AO20*AR20 -> 1.0156259 | AT20: =AM20*AP20/AS20 -> -0.29155508 | AU20: =AN20*AQ20/AS20 -> 1.1930139 | AV20: =ABS(AM20-AT19) -> 0.025443706 | AW20: =ABS(AN20-AU19) -> 0.020384905 | AX20: =AV20+AW20 -> 0.045828611 | AY20: =Inputs!$B$4*AV20+Inputs!$B$5*AW20 -> 3.3106758e-05 | AZ20: =(1-AY20)*AS20-1 -> 0.015592235 | BA20: =AZ20-D20 -> 0.014782463
A21: 2017-08 | B21: =MATCH(C21,Inputs!$D$2:$D$3,0) -> 2 | C21: =VALUE(LEFT(A21,4)) -> 2017 | D21: =EXP(SUMIFS(Daily!$L$2:$L$504,Daily!$B$2:$B$504,A21))-1 -> 0.00097041943 | E21: =EXP(SUMIFS(Daily!$J$2:$J$504,Daily!$B$2:$B$504,A21))-EXP(SUMIFS(Daily!$L$2:$L$504,Daily!$B$2:$B$504,A21)) -> -0.055259682 | F21: =SUMIFS(Daily!$H$2:$H$504,Daily!$B$2:$B$504,A21) -> 0.0013184076 | G21: =1/F21 -> 758.49075 | H21: =E22 -> 0.10158877 | I21: =H21*G21 -> 77.054143 | J21: =STDEV(H$2:H20)/STDEV(I$2:I20) -> 0.0014602952 | K21: =EXP(SUMIFS(Daily!$K$2:$K$504,Daily!$B$2:$B$504,A21))-EXP(SUMIFS(Daily!$L$2:$L$504,Daily!$B$2:$B$504,A21)) -> 0.0061321739 | L21: =SUMIFS(Daily!$I$2:$I$504,Daily!$B$2:$B$504,A21) -> 0.0020456471 | M21: =1/L21 -> 488.84287 | N21: =K22 -> -0.010495835 | O21: =N21*M21 -> -5.1308142 | P21: =STDEV(N$2:N20)/STDEV(O$2:O20) -> 0.0012378354 | Q21: =B22 -> 2 | R21: =IF(Q21=1,F21,L21) -> 0.0020456471 | S21: =IF(Q21=1,G21,M21) -> 488.84287 | T21: =IF(Q21=1,J21,P21) -> 0.0012378354 | U21: =T21*S21 -> 0.60510701 | V21: =MIN(Inputs!$B$2,MAX(0,U21)) -> 0.60510701 | W21: =V20 -> 0.51883274 | X21: =W21*INDEX(Inputs!$E$2:$E$3,B21) -> -0.15564982 | Y21: =W21*INDEX(Inputs!$F$2:$F$3,B21) -> 0.62259929 | Z21: =1-X21-Y21 -> 0.53305053 | AA21: =IF(X21<0,EXP(SUMIFS(Daily!$O$2:$O$504,Daily!$B$2:$B$504,A21)),EXP(SUMIFS(Daily!$M$2:$M$504,Daily!$B$2:$B$504,A21))) -> 0.9394703 | AB21: =IF(Y21<0,EXP(SUMIFS(Daily!$P$2:$P$504,Daily!$B$2:$B$504,A21)),EXP(SUMIFS(Daily!$N$2:$N$504,Daily!$B$2:$B$504,A21))) -> 0.99062769 | AC21: =IF(Z21<0,EXP(SUMIFS(Daily!$Q$2:$Q$504,Daily!$B$2:$B$504,A21)),1+D21) -> 1.0009704 | AD21: =X21*AA21+Y21*AB21+Z21*AC21 -> 1.0041035 | AE21: =X21*AA21/AD21 -> -0.14563079 | AF21: =Y21*AB21/AD21 -> 0.61424354 | AG21: =ABS(X21-AE20) -> 0.13088784 | AH21: =ABS(Y21-AF20) -> 0.54988386 | AI21: =AG21+AH21 -> 0.6807717 | AJ21: =Inputs!$B$4*AG21+Inputs!$B$5*AH21 -> 0.00061532778 | AK21: =(1-AJ21)*AD21-1 -> 0.0034856745 | AL21: =AK21-D21 -> 0.0025152551 | AM21: =1*INDEX(Inputs!$E$2:$E$3,B21) -> -0.3 | AN21: =1*INDEX(Inputs!$F$2:$F$3,B21) -> 1.2 | AO21: =1-AM21-AN21 -> 0.1 | AP21: =IF(AM21<0,EXP(SUMIFS(Daily!$O$2:$O$504,Daily!$B$2:$B$504,A21)),EXP(SUMIFS(Daily!$M$2:$M$504,Daily!$B$2:$B$504,A21))) -> 0.9394703 | AQ21: =IF(AN21<0,EXP(SUMIFS(Daily!$P$2:$P$504,Daily!$B$2:$B$504,A21)),EXP(SUMIFS(Daily!$N$2:$N$504,Daily!$B$2:$B$504,A21))) -> 0.99062769 | AR21: =IF(AO21<0,EXP(SUMIFS(Daily!$Q$2:$Q$504,Daily!$B$2:$B$504,A21)),1+D21) -> 1.0009704 | AS21: =AM21*AP21+AN21*AQ21+AO21*AR21 -> 1.0070092 | AT21: =AM21*AP21/AS21 -> -0.27987937 | AU21: =AN21*AQ21/AS21 -> 1.180479 | AV21: =ABS(AM21-AT20) -> 0.0084449228 | AW21: =ABS(AN21-AU20) -> 0.0069861093 | AX21: =AV21+AW21 -> 0.015431032 | AY21: =Inputs!$B$4*AV21+Inputs!$B$5*AW21 -> 1.1208571e-05 | AZ21: =(1-AY21)*AS21-1 -> 0.0069978951 | BA21: =AZ21-D21 -> 0.0060274756
... A24: 2017-11 | B24: =MATCH(C24,Inputs!$D$2:$D$3,0) -> 2 | C24: =VALUE(LEFT(A24,4)) -> 2017 | D24: =EXP(SUMIFS(Daily!$L$2:$L$504,Daily!$B$2:$B$504,A24))-1 -> 0.00099233448 | E24: =EXP(SUMIFS(Daily!$J$2:$J$504,Daily!$B$2:$B$504,A24))-EXP(SUMIFS(Daily!$L$2:$L$504,Daily!$B$2:$B$504,A24)) -> 0.047517151 | F24: =SUMIFS(Daily!$H$2:$H$504,Daily!$B$2:$B$504,A24) -> 0.0022500165 | G24: =1/F24 -> 444.44119 | H24: =E25 -> -0.0089968064 | I24: =H24*G24 -> -3.9985513 | J24: =STDEV(H$2:H23)/STDEV(I$2:I23) -> 0.0014392595 | K24: =EXP(SUMIFS(Daily!$K$2:$K$504,Daily!$B$2:$B$504,A24))-EXP(SUMIFS(Daily!$L$2:$L$504,Daily!$B$2:$B$504,A24)) -> 0.036744286 | L24: =SUMIFS(Daily!$I$2:$I$504,Daily!$B$2:$B$504,A24) -> 0.0011912298 | M24: =1/L24 -> 839.46862 | N24: =K25 -> -0.0034044059 | O24: =N24*M24 -> -2.8578919 | P24: =STDEV(N$2:N23)/STDEV(O$2:O23) -> 0.0012924736 | Q24: =B25 -> 2 | R24: =IF(Q24=1,F24,L24) -> 0.0011912298 | S24: =IF(Q24=1,G24,M24) -> 839.46862 | T24: =IF(Q24=1,J24,P24) -> 0.0012924736 | U24: =T24*S24 -> 1.084991 | V24: =MIN(Inputs!$B$2,MAX(0,U24)) -> 1.084991 | W24: =V23 -> 1.2033987 | X24: =W24*INDEX(Inputs!$E$2:$E$3,B24) -> -0.3610196 | Y24: =W24*INDEX(Inputs!$F$2:$F$3,B24) -> 1.4440784 | Z24: =1-X24-Y24 -> -0.083058803 | AA24: =IF(X24<0,EXP(SUMIFS(Daily!$O$2:$O$504,Daily!$B$2:$B$504,A24)),EXP(SUMIFS(Daily!$M$2:$M$504,Daily!$B$2:$B$504,A24))) -> 1.0311201 | AB24: =IF(Y24<0,EXP(SUMIFS(Daily!$P$2:$P$504,Daily!$B$2:$B$504,A24)),EXP(SUMIFS(Daily!$N$2:$N$504,Daily!$B$2:$B$504,A24))) -> 1.0395528 | AC24: =IF(Z24<0,EXP(SUMIFS(Daily!$Q$2:$Q$504,Daily!$B$2:$B$504,A24)),1+D24) -> 1.0014095 | AD24: =X24*AA24+Y24*AB24+Z24*AC24 -> 1.0457653 | AE24: =X24*AA24/AD24 -> -0.3559638 | AF24: =Y24*AB24/AD24 -> 1.4354997 | AG24: =ABS(X24-AE23) -> 0.058672957 | AH24: =ABS(Y24-AF23) -> 0.37278196 | AI24: =AG24+AH24 -> 0.43145492 | AJ24: =Inputs!$B$4*AG24+Inputs!$B$5*AH24 -> 0.00040211844 | AK24: =(1-AJ24)*AD24-1 -> 0.045344749 | AL24: =AK24-D24 -> 0.044352415 | AM24: =1*INDEX(Inputs!$E$2:$E$3,B24) -> -0.3 | AN24: =1*INDEX(Inputs!$F$2:$F$3,B24) -> 1.2 | AO24: =1-AM24-AN24 -> 0.1 | AP24: =IF(AM24<0,EXP(SUMIFS(Daily!$O$2:$O$504,Daily!$B$2:$B$504,A24)),EXP(SUMIFS(Daily!$M$2:$M$504,Daily!$B$2:$B$504,A24))) -> 1.0311201 | AQ24: =IF(AN24<0,EXP(SUMIFS(Daily!$P$2:$P$504,Daily!$B$2:$B$504,A24)),EXP(SUMIFS(Daily!$N$2:$N$504,Daily!$B$2:$B$504,A24))) -> 1.0395528 | AR24: =IF(AO24<0,EXP(SUMIFS(Daily!$Q$2:$Q$504,Daily!$B$2:$B$504,A24)),1+D24) -> 1.0009923 | AS24: =AM24*AP24+AN24*AQ24+AO24*AR24 -> 1.0382265 | AT24: =AM24*AP24/AS24 -> -0.29794658 | AU24: =AN24*AQ24/AS24 -> 1.2015329 | AV24: =ABS(AM24-AT23) -> 0.050257864 | AW24: =ABS(AN24-AU23) -> 0.041058929 | AX24: =AV24+AW24 -> 0.091316793 | AY24: =Inputs!$B$4*AV24+Inputs!$B$5*AW24 -> 6.6187861e-05 | AZ24: =(1-AY24)*AS24-1 -> 0.038157814 | BA24: =AZ24-D24 -> 0.037165479
A25: 2017-12 | B25: =MATCH(C25,Inputs!$D$2:$D$3,0) -> 2 | C25: =VALUE(LEFT(A25,4)) -> 2017 | D25: =EXP(SUMIFS(Daily!$L$2:$L$504,Daily!$B$2:$B$504,A25))-1 -> 0.00097749778 | E25: =EXP(SUMIFS(Daily!$J$2:$J$504,Daily!$B$2:$B$504,A25))-EXP(SUMIFS(Daily!$L$2:$L$504,Daily!$B$2:$B$504,A25)) -> -0.0089968064 | F25: =SUMIFS(Daily!$H$2:$H$504,Daily!$B$2:$B$504,A25) -> 0.0010249638 | G25: =1/F25 -> 975.64421 | J25: =STDEV(H$2:H24)/STDEV(I$2:I24) -> 0.0014414504 | K25: =EXP(SUMIFS(Daily!$K$2:$K$504,Daily!$B$2:$B$504,A25))-EXP(SUMIFS(Daily!$L$2:$L$504,Daily!$B$2:$B$504,A25)) -> -0.0034044059 | L25: =SUMIFS(Daily!$I$2:$I$504,Daily!$B$2:$B$504,A25) -> 0.00046987002 | M25: =1/L25 -> 2128.2481 | P25: =STDEV(N$2:N24)/STDEV(O$2:O24) -> 0.0012934757 | W25: =V24 -> 1.084991 | X25: =W25*INDEX(Inputs!$E$2:$E$3,B25) -> -0.3254973 | Y25: =W25*INDEX(Inputs!$F$2:$F$3,B25) -> 1.3019892 | Z25: =1-X25-Y25 -> 0.023508092 | AA25: =IF(X25<0,EXP(SUMIFS(Daily!$O$2:$O$504,Daily!$B$2:$B$504,A25)),EXP(SUMIFS(Daily!$M$2:$M$504,Daily!$B$2:$B$504,A25))) -> 0.99319826 | AB25: =IF(Y25<0,EXP(SUMIFS(Daily!$P$2:$P$504,Daily!$B$2:$B$504,A25)),EXP(SUMIFS(Daily!$N$2:$N$504,Daily!$B$2:$B$504,A25))) -> 0.99638955 | AC25: =IF(Z25<0,EXP(SUMIFS(Daily!$Q$2:$Q$504,Daily!$B$2:$B$504,A25)),1+D25) -> 1.0009775 | AD25: =X25*AA25+Y25*AB25+Z25*AC25 -> 0.99753617 | AE25: =X25*AA25/AD25 -> -0.32408184 | AF25: =Y25*AB25/AD25 -> 1.3004926 | AG25: =ABS(X25-AE24) -> 0.0304665 | AH25: =ABS(Y25-AF24) -> 0.13351048 | AI25: =AG25+AH25 -> 0.16397698 | AJ25: =Inputs!$B$4*AG25+Inputs!$B$5*AH25 -> 0.00014874373 | AK25: =(1-AJ25)*AD25-1 -> -0.0026122117 | AL25: =AK25-D25 -> -0.0035897095 | AM25: =1*INDEX(Inputs!$E$2:$E$3,B25) -> -0.3 | AN25: =1*INDEX(Inputs!$F$2:$F$3,B25) -> 1.2 | AO25: =1-AM25-AN25 -> 0.1 | AP25: =IF(AM25<0,EXP(SUMIFS(Daily!$O$2:$O$504,Daily!$B$2:$B$504,A25)),EXP(SUMIFS(Daily!$M$2:$M$504,Daily!$B$2:$B$504,A25))) -> 0.99319826 | AQ25: =IF(AN25<0,EXP(SUMIFS(Daily!$P$2:$P$504,Daily!$B$2:$B$504,A25)),EXP(SUMIFS(Daily!$N$2:$N$504,Daily!$B$2:$B$504,A25))) -> 0.99638955 | AR25: =IF(AO25<0,EXP(SUMIFS(Daily!$Q$2:$Q$504,Daily!$B$2:$B$504,A25)),1+D25) -> 1.0009775 | AS25: =AM25*AP25+AN25*AQ25+AO25*AR25 -> 0.99780574 | AT25: =AM25*AP25/AS25 -> -0.29861472 | AU25: =AN25*AQ25/AS25 -> 1.1982968 | AV25: =ABS(AM25-AT24) -> 0.0020534215 | AW25: =ABS(AN25-AU24) -> 0.0015329054 | AX25: =AV25+AW25 -> 0.0035863269 | AY25: =Inputs!$B$4*AV25+Inputs!$B$5*AW25 -> 2.5596162e-06 | AZ25: =(1-AY25)*AS25-1 -> -0.0021968173 | BA25: =AZ25-D25 -> -0.0031743151

Sheet Daily
A1: date | B1: month | C1: x_A | D1: x_B | E1: rf | F1: p1 | G1: p2 | H1: p1^2 | I1: p2^2 | J1: ln(1+p1+rf) | K1: ln(1+p2+rf) | L1: ln(1+rf) | M1: ln(1+x_A+rf) | N1: ln(1+x_B+rf) | O1: ln(1+x_A+rf+fee_A) | P1: ln(1+x_B+rf+fee_B) | Q1: ln(1+rf+spread)
A2: 42373 | B2: 2016-01 | C2: 0.0016771548 | D2: -0.00036234479 | E2: 9.9206349e-06 | F2: =Inputs!$E$2*C2+Inputs!$F$2*D2 -> 0.0011243169 | G2: =Inputs!$E$3*C2+Inputs!$F$3*D2 -> -0.00093796018 | H2: =F2^2 -> 1.2640886e-06 | I2: =G2^2 -> 8.797693e-07 | J2: =LN(1+F2+E2) -> 0.0011335948 | K2: =LN(1+G2+E2) -> -0.00092847044 | L2: =LN(1+E2) -> 9.9205857e-06 | M2: =LN(1+C2+E2) -> 0.0016856539 | N2: =LN(1+D2+E2) -> -0.00035248628 | O2: =LN(1+C2+E2+Inputs!$B$7/Inputs!$B$9) -> 0.0016955578 | P2: =LN(1+D2+E2+Inputs!$B$8/Inputs!$B$9) -> -0.00035248628 | Q2: =LN(1+E2+Inputs!$B$6/Inputs!$B$9) -> 2.9761462e-05
A3: 42374 | B3: 2016-01 | C3: -0.010835433 | D3: 0.012142357 | E3: 9.9996838e-06 | F3: =Inputs!$E$2*C3+Inputs!$F$2*D3 -> -0.0013829322 | G3: =Inputs!$E$3*C3+Inputs!$F$3*D3 -> 0.017821458 | H3: =F3^2 -> 1.9125013e-06 | I3: =G3^2 -> 0.00031760437 | J3: =LN(1+F3+E3) -> -0.0013738758 | K3: =LN(1+G3+E3) -> 0.017674342 | L3: =LN(1+E3) -> 9.9996338e-06 | M3: =LN(1+C3+E3) -> -0.010884454 | N3: =LN(1+D3+E3) -> 0.012079109 | O3: =LN(1+C3+E3+Inputs!$B$7/Inputs!$B$9) -> -0.010874425 | P3: =LN(1+D3+E3+Inputs!$B$8/Inputs!$B$9) -> 0.012079109 | Q3: =LN(1+E3+Inputs!$B$6/Inputs!$B$9) -> 2.9840508e-05
A4: 42375 | B4: 2016-01 | C4: -0.0037318549 | D4: 0.0040694571 | E4: 1.0078733e-05 | F4: =Inputs!$E$2*C4+Inputs!$F$2*D4 -> -0.00054380962 | G4: =Inputs!$E$3*C4+Inputs!$F$3*D4 -> 0.006002905 | H4: =F4^2 -> 2.9572891e-07 | I4: =G4^2 -> 3.6034869e-05 | J4: =LN(1+F4+E4) -> -0.00053387338 | K4: =LN(1+G4+E4) -> 0.0059949779 | L4: =LN(1+E4) -> 1.0078682e-05 | M4: =LN(1+C4+E4) -> -0.0037287192 | N4: =LN(1+D4+E4) -> 0.0040712371 | O4: =LN(1+C4+E4+Inputs!$B$7/Inputs!$B$9) -> -0.0037187615 | P4: =LN(1+D4+E4+Inputs!$B$8/Inputs!$B$9) -> 0.0040712371 | Q4: =LN(1+E4+Inputs!$B$6/Inputs!$B$9) -> 2.9919555e-05
A5: 42376 | B5: 2016-01 | C5: 0.0059059975 | D5: -0.0018247831 | E5: 1.0157782e-05 | F5: =Inputs!$E$2*C5+Inputs!$F$2*D5 -> 0.0036299281 | G5: =Inputs!$E$3*C5+Inputs!$F$3*D5 -> -0.003961539 | H5: =F5^2 -> 1.3176378e-05 | I5: =G5^2 -> 1.5693791e-05 | J5: =LN(1+F5+E5) -> 0.0036334768 | K5: =LN(1+G5+E5) -> -0.0039592086 | L5: =LN(1+E5) -> 1.015773e-05 | M5: =LN(1+C5+E5) -> 0.0058987235 | N5: =LN(1+D5+E5) -> -0.0018162738 | O5: =LN(1+C5+E5+Inputs!$B$7/Inputs!$B$9) -> 0.0059085858 | P5: =LN(1+D5+E5+Inputs!$B$8/Inputs!$B$9) -> -0.0018162738 | Q5: =LN(1+E5+Inputs!$B$6/Inputs!$B$9) -> 2.9998601e-05
A6: 42377 | B6: 2016-01 | C6: 0.0061875458 | D6: -0.0035388887 | E6: 1.023683e-05 | F6: =Inputs!$E$2*C6+Inputs!$F$2*D6 -> 0.0028267034 | G6: =Inputs!$E$3*C6+Inputs!$F$3*D6 -> -0.0061029302 | H6: =F6^2 -> 7.9902522e-06 | I6: =G6^2 -> 3.7245757e-05 | J6: =LN(1+F6+E6) -> 0.0028329237 | K6: =LN(1+G6+E6) -> -0.0061113296 | L6: =LN(1+E6) -> 1.0236778e-05 | M6: =LN(1+C6+E6) -> 0.0061786554 | N6: =LN(1+D6+E6) -> -0.0035348923 | O6: =LN(1+C6+E6+Inputs!$B$7/Inputs!$B$9) -> 0.0061885149 | P6: =LN(1+D6+E6+Inputs!$B$8/Inputs!$B$9) -> -0.0035348923 | Q6: =LN(1+E6+Inputs!$B$6/Inputs!$B$9) -> 3.0077648e-05
A7: 42380 | B7: 2016-01 | C7: -0.0013417193 | D7: 0.00028035804 | E7: 1.0315879e-05 | F7: =Inputs!$E$2*C7+Inputs!$F$2*D7 -> -0.00090516064 | G7: =Inputs!$E$3*C7+Inputs!$F$3*D7 -> 0.00073894544 | H7: =F7^2 -> 8.1931578e-07 | I7: =G7^2 -> 5.4604037e-07 | J7: =LN(1+F7+E7) -> -0.00089524537 | K7: =LN(1+G7+E7) -> 0.00074898077 | L7: =LN(1+E7) -> 1.0315826e-05 | M7: =LN(1+C7+E7) -> -0.0013322906 | N7: =LN(1+D7+E7) -> 0.00029063168 | O7: =LN(1+C7+E7+Inputs!$B$7/Inputs!$B$9) -> -0.0013223567 | P7: =LN(1+D7+E7+Inputs!$B$8/Inputs!$B$9) -> 0.00029063168 | Q7: =LN(1+E7+Inputs!$B$6/Inputs!$B$9) -> 3.0156694e-05
A8: 42381 | B8: 2016-01 | C8: 0.0041173701 | D8: -0.0058626816 | E8: 1.0394928e-05 | F8: =Inputs!$E$2*C8+Inputs!$F$2*D8 -> -0.00022371287 | G8: =Inputs!$E$3*C8+Inputs!$F$3*D8 -> -0.0082704289 | H8: =F8^2 -> 5.0047447e-08 | I8: =G8^2 -> 6.8399994e-05 | J8: =LN(1+F8+E8) -> -0.00021334069 | K8: =LN(1+G8+E8) -> -0.0082943371 | L8: =LN(1+E8) -> 1.0394874e-05 | M8: =LN(1+C8+E8) -> 0.0041192692 | N8: =LN(1+D8+E8) -> -0.0058694784 | O8: =LN(1+C8+E8+Inputs!$B$7/Inputs!$B$9) -> 0.004129149 | P8: =LN(1+D8+E8+Inputs!$B$8/Inputs!$B$9) -> -0.0058694784 | Q8: =LN(1+E8+Inputs!$B$6/Inputs!$B$9) -> 3.0235741e-05
A9: 42382 | B9: 2016-01 | C9: 0.00077336801 | D9: 0.0075071318 | E9: 1.0473977e-05 | F9: =Inputs!$E$2*C9+Inputs!$F$2*D9 -> 0.0051229735 | G9: =Inputs!$E$3*C9+Inputs!$F$3*D9 -> 0.0087765477 | H9: =F9^2 -> 2.6244857e-05 | I9: =G9^2 -> 7.702779e-05 | J9: =LN(1+F9+E9) -> 0.0051203162 | K9: =LN(1+G9+E9) -> 0.0087486405 | L9: =LN(1+E9) -> 1.0473922e-05 | M9: =LN(1+C9+E9) -> 0.00078353494 | N9: =LN(1+D9+E9) -> 0.0074894894 | O9: =LN(1+C9+E9+Inputs!$B$7/Inputs!$B$9) -> 0.00079344776 | P9: =LN(1+D9+E9+Inputs!$B$8/Inputs!$B$9) -> 0.0074894894 | Q9: =LN(1+E9+Inputs!$B$6/Inputs!$B$9) -> 3.0314787e-05
A10: 42383 | B10: 2016-01 | C10: -0.016865191 | D10: -0.0062738545 | E10: 1.0553026e-05 | F10: =Inputs!$E$2*C10+Inputs!$F$2*D10 -> -0.017256466 | G10: =Inputs!$E$3*C10+Inputs!$F$3*D10 -> -0.0024690681 | H10: =F10^2 -> 0.0002977856 | I10: =G10^2 -> 6.0962971e-06 | J10: =LN(1+F10+E10) -> -0.017396356 | K10: =LN(1+G10+E10) -> -0.0024615421 | L10: =LN(1+E10) -> 1.055297e-05 | M10: =LN(1+C10+E10) -> -0.016998294 | N10: =LN(1+D10+E10) -> -0.0062829982 | O10: =LN(1+C10+E10+Inputs!$B$7/Inputs!$B$9) -> -0.016988203 | P10: =LN(1+D10+E10+Inputs!$B$8/Inputs!$B$9) -> -0.0062829982 | Q10: =LN(1+E10+Inputs!$B$6/Inputs!$B$9) -> 3.0393834e-05
A11: 42384 | B11: 2016-01 | C11: -0.032504593 | D11: 0.0042413957 | E11: 1.0632075e-05 | F11: =Inputs!$E$2*C11+Inputs!$F$2*D11 -> -0.023458837 | G11: =Inputs!$E$3*C11+Inputs!$F$3*D11 -> 0.014841053 | H11: =F11^2 -> 0.00055031704 | I11: =G11^2 -> 0.00022025685 | J11: =LN(1+F11+E11) -> -0.023727489 | K11: =LN(1+G11+E11) -> 0.014742478 | L11: =LN(1+E11) -> 1.0632018e-05 | M11: =LN(1+C11+E11) -> -0.033033612 | N11: =LN(1+D11+E11) -> 0.0042430134 | O11: =LN(1+C11+E11+Inputs!$B$7/Inputs!$B$9) -> -0.033023358 | P11: =LN(1+D11+E11+Inputs!$B$8/Inputs!$B$9) -> 0.0042430134 | Q11: =LN(1+E11+Inputs!$B$6/Inputs!$B$9) -> 3.047288e-05
